Workbook

Sheet Dashboard
AT1: Day | AU1: Actual | AV1: Pace | AY1: ='Team Leaderboard'!$E$4+0/100000 -> 42
B2: STORE PERFORMANCE | AG2: MOCK DATA | AT2: 1 | AU2: =SUM('1'!Q16)+SUM('1'!R16) -> 18 | AV2: =('Store Total'!$C$4+'Store Total'!$C$5)*1/31 -> 16.451613 | AY2: ='Team Leaderboard'!$E$5+1/100000 -> 54.00001
B3: Monthly tracker · all figures generated, not real | AT3: 2 | AU3: =SUM('1:2'!Q16)+SUM('1:2'!R16) -> 34 | AV3: =('Store Total'!$C$4+'Store Total'!$C$5)*2/31 -> 32.903226 | AY3: ='Team Leaderboard'!$E$6+2/100000 -> 47.00002
AT4: 3 | AU4: =SUM('1:3'!Q16)+SUM('1:3'!R16) -> 57 | AV4: =('Store Total'!$C$4+'Store Total'!$C$5)*3/31 -> 49.354839 | AY4: ='Team Leaderboard'!$E$7+3/100000 -> 39.00003
AT5: 4 | AU5: =SUM('1:4'!Q16)+SUM('1:4'!R16) -> 67 | AV5: =('Store Total'!$C$4+'Store Total'!$C$5)*4/31 -> 65.806452 | AY5: ='Team Leaderboard'!$E$8+4/100000 -> 36.00004
C6: ACTS + PRE — MONTH TO DATE | T6: TEAM | AT6: 5 | AU6: =SUM('1:5'!Q16)+SUM('1:5'!R16) -> 92 | AV6: =('Store Total'!$C$4+'Store Total'!$C$5)*5/31 -> 82.258065 | AY6: ='Team Leaderboard'!$E$9+5/100000 -> 53.00005
C7: ='Store Total'!B4+'Store Total'!B5 -> 524 | K7: GOAL | T7: =INDEX('Team Leaderboard'!$B$4:$B$15,MATCH(LARGE($AY$1:$AY$12,1),$AY$1:$AY$12,0)) -> Expert 12 | AA7: =INDEX('Team Leaderboard'!$E$4:$E$15,MATCH(LARGE($AY$1:$AY$12,1),$AY$1:$AY$12,0)) -> 55 | AT7: 6 | AU7: =SUM('1:6'!Q16)+SUM('1:6'!R16) -> 106 | AV7: =('Store Total'!$C$4+'Store Total'!$C$5)*6/31 -> 98.709677 | AY7: ='Team Leaderboard'!$E$10+6/100000 -> 33.00006
K8: ='Store Total'!C4+'Store Total'!C5 -> 510 | T8: =INDEX('Team Leaderboard'!$B$4:$B$15,MATCH(LARGE($AY$1:$AY$12,2),$AY$1:$AY$12,0)) -> Expert 02 | AA8: =INDEX('Team Leaderboard'!$E$4:$E$15,MATCH(LARGE($AY$1:$AY$12,2),$AY$1:$AY$12,0)) -> 54 | AT8: 7 | AU8: =SUM('1:7'!Q16)+SUM('1:7'!R16) -> 115 | AV8: =('Store Total'!$C$4+'Store Total'!$C$5)*7/31 -> 115.16129 | AY8: ='Team Leaderboard'!$E$11+7/100000 -> 43.00007
T9: =INDEX('Team Leaderboard'!$B$4:$B$15,MATCH(LARGE($AY$1:$AY$12,3),$AY$1:$AY$12,0)) -> Expert 06 | AA9: =INDEX('Team Leaderboard'!$E$4:$E$15,MATCH(LARGE($AY$1:$AY$12,3),$AY$1:$AY$12,0)) -> 53 | AT9: 8 | AU9: =SUM('1:8'!Q16)+SUM('1:8'!R16) -> 136 | AV9: =('Store Total'!$C$4+'Store Total'!$C$5)*8/31 -> 131.6129 | AY9: ='Team Leaderboard'!$E$12+8/100000 -> 28.00008
C10: =TEXT(('Store Total'!B4+'Store Total'!B5)/('Store Total'!C4+'Store Total'!C5),"0%")&" of goal" -> 103% of goal | K10: =TEXT(('Store Total'!B4+'Store Total'!B5)-('Store Total'!C4+'Store Total'!C5),"+#,##0;-#,##0")&" vs goal" -> +14 vs goal | AT10: 9 | AU10: =SUM('1:9'!Q16)+SUM('1:9'!R16) -> 153 | AV10: =('Store Total'!$C$4+'Store Total'!$C$5)*9/31 -> 148.06452 | AY10: ='Team Leaderboard'!$E$13+9/100000 -> 46.00009
C11: =('Store Total'!B4+'Store Total'!B5)/('Store Total'!C4+'Store Total'!C5) -> 1.027451 | T11: =INDEX('Team Leaderboard'!$B$4:$B$15,MATCH(SMALL($AY$1:$AY$12,1),$AY$1:$AY$12,0)) -> Expert 09 | AA11: =INDEX('Team Leaderboard'!$E$4:$E$15,MATCH(SMALL($AY$1:$AY$12,1),$AY$1:$AY$12,0)) -> 28 | AT11: 10 | AU11: =SUM('1:10'!Q16)+SUM('1:10'!R16) -> 170 | AV11: =('Store Total'!$C$4+'Store Total'!$C$5)*10/31 -> 164.51613 | AY11: ='Team Leaderboard'!$E$14+10/100000 -> 48.0001
AT12: 11 | AU12: =SUM('1:11'!Q16)+SUM('1:11'!R16) -> 181 | AV12: =('Store Total'!$C$4+'Store Total'!$C$5)*11/31 -> 180.96774 | AY12: ='Team Leaderboard'!$E$15+11/100000 -> 55.00011
AT13: 12 | AU13: =SUM('1:12'!Q16)+SUM('1:12'!R16) -> 199 | AV13: =('Store Total'!$C$4+'Store Total'!$C$5)*12/31 -> 197.41935
AT14: 13 | AU14: =SUM('1:13'!Q16)+SUM('1:13'!R16) -> 224 | AV14: =('Store Total'!$C$4+'Store Total'!$C$5)*13/31 -> 213.87097
C15: ACTIVATIONS | I15: =TEXT('Store Total'!D4,"0%") -> 104% | N15: PREPAID | T15: =TEXT('Store Total'!D5,"0%") -> 99% | Y15: DEVICES | AE15: =TEXT('Store Total'!D10,"0%") -> 106% | AJ15: ACCESSORY $ | AP15: =TEXT('Store Total'!D11,"0%") -> 98% | AT15: 14 | AU15: =SUM('1:14'!Q16)+SUM('1:14'!R16) -> 244 | AV15: =('Store Total'!$C$4+'Store Total'!$C$5)*14/31 -> 230.32258
C16: ='Store Total'!B4 -> 381 | N16: ='Store Total'!B5 -> 143 | Y16: ='Store Total'!B10 -> 635 | AJ16: ='Store Total'!B11 -> 38698.71 | AT16: 15 | AU16: =SUM('1:15'!Q16)+SUM('1:15'!R16) -> 259 | AV16: =('Store Total'!$C$4+'Store Total'!$C$5)*15/31 -> 246.77419
C17: ='Store Total'!D4 -> 1.0438356 | N17: ='Store Total'!D5 -> 0.9862069 | Y17: ='Store Total'!D10 -> 1.0583333 | AJ17: ='Store Total'!D11 -> 0.97971418 | AT17: 16 | AU17: =SUM('1:16'!Q16)+SUM('1:16'!R16) -> 281 | AV17: =('Store Total'!$C$4+'Store Total'!$C$5)*16/31 -> 263.22581
AT18: 17 | AU18: =SUM('1:17'!Q16)+SUM('1:17'!R16) -> 293 | AV18: =('Store Total'!$C$4+'Store Total'!$C$5)*17/31 -> 279.67742
AT19: 18 | AU19: =SUM('1:18'!Q16)+SUM('1:18'!R16) -> 317 | AV19: =('Store Total'!$C$4+'Store Total'!$C$5)*18/31 -> 296.12903
AT20: 19 | AU20: =SUM('1:19'!Q16)+SUM('1:19'!R16) -> 333 | AV20: =('Store Total'!$C$4+'Store Total'!$C$5)*19/31 -> 312.58065
C21: BTS | I21: =TEXT('Store Total'!D7,"0%") -> 95% | N21: HOME INTERNET | T21: =TEXT('Store Total'!D8,"0%") -> 101% | Y21: TFB | AE21: =TEXT('Store Total'!D6,"0%") -> 105% | AJ21: VALUE-ADD $ | AP21: =TEXT('Store Total'!D9,"0%") -> 102% | AT21: 20 | AU21: =SUM('1:20'!Q16)+SUM('1:20'!R16) -> 355 | AV21: =('Store Total'!$C$4+'Store Total'!$C$5)*20/31 -> 329.03226
C22: ='Store Total'!B7 -> 38 | N22: ='Store Total'!B8 -> 76 | Y22: ='Store Total'!B6 -> 42 | AJ22: ='Store Total'!B9 -> 7865 | AT22: 21 | AU22: =SUM('1:21'!Q16)+SUM('1:21'!R16) -> 372 | AV22: =('Store Total'!$C$4+'Store Total'!$C$5)*21/31 -> 345.48387
C23: ='Store Total'!D7 -> 0.95 | N23: ='Store Total'!D8 -> 1.0133333 | Y23: ='Store Total'!D6 -> 1.05 | AJ23: ='Store Total'!D9 -> 1.0214286 | AT23: 22 | AU23: =SUM('1:22'!Q16)+SUM('1:22'!R16) -> 393 | AV23: =('Store Total'!$C$4+'Store Total'!$C$5)*22/31 -> 361.93548
AT24: 23 | AU24: =SUM('1:23'!Q16)+SUM('1:23'!R16) -> 407 | AV24: =('Store Total'!$C$4+'Store Total'!$C$5)*23/31 -> 378.3871
AT25: 24 | AU25: =SUM('1:24'!Q16)+SUM('1:24'!R16) -> 422 | AV25: =('Store Total'!$C$4+'Store Total'!$C$5)*24/31 -> 394.83871
AT26: 25 | AU26: =SUM('1:25'!Q16)+SUM('1:25'!R16) -> 435 | AV26: =('Store Total'!$C$4+'Store Total'!$C$5)*25/31 -> 411.29032
C27: PACE TO GOAL — cumulative Acts + Pre vs required pace | AT27: 26 | AU27: =SUM('1:26'!Q16)+SUM('1:26'!R16) -> 449 | AV27: =('Store Total'!$C$4+'Store Total'!$C$5)*26/31 -> 427.74194
AT28: 27 | AU28: =SUM('1:27'!Q16)+SUM('1:27'!R16) -> 460 | AV28: =('Store Total'!$C$4+'Store Total'!$C$5)*27/31 -> 444.19355
AT29: 28 | AU29: =SUM('1:28'!Q16)+SUM('1:28'!R16) -> 475 | AV29: =('Store Total'!$C$4+'Store Total'!$C$5)*28/31 -> 460.64516
AT30: 29 | AU30: =SUM('1:29'!Q16)+SUM('1:29'!R16) -> 492 | AV30: =('Store Total'!$C$4+'Store Total'!$C$5)*29/31 -> 477.09677
AT31: 30 | AU31: =SUM('1:30'!Q16)+SUM('1:30'!R16) -> 505 | AV31: =('Store Total'!$C$4+'Store Total'!$C$5)*30/31 -> 493.54839
AT32: 31 | AU32: =SUM('1:31'!Q16)+SUM('1:31'!R16) -> 524 | AV32: =('Store Total'!$C$4+'Store Total'!$C$5)*31/31 -> 510

Sheet Team Leaderboard
A1: Team Leaderboard — ranked by Acts + Pre
A2: MOCK DATA — generated for portfolio use. No real employees, customers, device identifiers, or store numbers appear in this file.
A3: Rank | B3: Mobile Expert | C3: Acts | D3: Pre | E3: Acts + Pre | F3: Acc $
A4: =RANK(E4,$E$4:$E$15) -> 8 | B4: =Setup!$A$4 -> Expert 01 | C4: =SUM('1:31'!Q4) -> 30 | D4: =SUM('1:31'!R4) -> 12 | E4: =C4+D4 -> 42 | F4: =SUM('1:31'!X4) -> 3596.91
A5: =RANK(E5,$E$4:$E$15) -> 2 | B5: =Setup!$A$5 -> Expert 02 | C5: =SUM('1:31'!Q5) -> 43 | D5: =SUM('1:31'!R5) -> 11 | E5: =C5+D5 -> 54 | F5: =SUM('1:31'!X5) -> 3011.88
A6: =RANK(E6,$E$4:$E$15) -> 5 | B6: =Setup!$A$6 -> Expert 03 | C6: =SUM('1:31'!Q6) -> 30 | D6: =SUM('1:31'!R6) -> 17 | E6: =C6+D6 -> 47 | F6: =SUM('1:31'!X6) -> 3435.23
A7: =RANK(E7,$E$4:$E$15) -> 9 | B7: =Setup!$A$7 -> Expert 04 | C7: =SUM('1:31'!Q7) -> 35 | D7: =SUM('1:31'!R7) -> 4 | E7: =C7+D7 -> 39 | F7: =SUM('1:31'!X7) -> 3112.85
A8: =RANK(E8,$E$4:$E$15) -> 10 | B8: =Setup!$A$8 -> Expert 05 | C8: =SUM('1:31'!Q8) -> 24 | D8: =SUM('1:31'!R8) -> 12 | E8: =C8+D8 -> 36 | F8: =SUM('1:31'!X8) -> 3203.83
A9: =RANK(E9,$E$4:$E$15) -> 3 | B9: =Setup!$A$9 -> Expert 06 | C9: =SUM('1:31'!Q9) -> 39 | D9: =SUM('1:31'!R9) -> 14 | E9: =C9+D9 -> 53 | F9: =SUM('1:31'!X9) -> 4028.5
A10: =RANK(E10,$E$4:$E$15) -> 11 | B10: =Setup!$A$10 -> Expert 07 | C10: =SUM('1:31'!Q10) -> 23 | D10: =SUM('1:31'!R10) -> 10 | E10: =C10+D10 -> 33 | F10: =SUM('1:31'!X10) -> 1969.02
A11: =RANK(E11,$E$4:$E$15) -> 7 | B11: =Setup!$A$11 -> Expert 08 | C11: =SUM('1:31'!Q11) -> 33 | D11: =SUM('1:31'!R11) -> 10 | E11: =C11+D11 -> 43 | F11: =SUM('1:31'!X11) -> 2772.13
A12: =RANK(E12,$E$4:$E$15) -> 12 | B12: =Setup!$A$12 -> Expert 09 | C12: =SUM('1:31'!Q12) -> 21 | D12: =SUM('1:31'!R12) -> 7 | E12: =C12+D12 -> 28 | F12: =SUM('1:31'!X12) -> 2526.05
A13: =RANK(E13,$E$4:$E$15) -> 6 | B13: =Setup!$A$13 -> Expert 10 | C13: =SUM('1:31'!Q13) -> 34 | D13: =SUM('1:31'!R13) -> 12 | E13: =C13+D13 -> 46 | F13: =SUM('1:31'!X13) -> 2870.48
A14: =RANK(E14,$E$4:$E$15) -> 4 | B14: =Setup!$A$14 -> Expert 11 | C14: =SUM('1:31'!Q14) -> 35 | D14: =SUM('1:31'!R14) -> 13 | E14: =C14+D14 -> 48 | F14: =SUM('1:31'!X14) -> 3904.91
A15: =RANK(E15,$E$4:$E$15) -> 1 | B15: =Setup!$A$15 -> Expert 12 | C15: =SUM('1:31'!Q15) -> 34 | D15: =SUM('1:31'!R15) -> 21 | E15: =C15+D15 -> 55 | F15: =SUM('1:31'!X15) -> 4266.92

Sheet Daily Trend
A1: Daily Trend — heatmap by day
A2: MOCK DATA — generated for portfolio use. No real employees, customers, device identifiers, or store numbers appear in this file.
A3: Day | B3: Acts | C3: Pre | D3: TFB | E3: BTS | F3: Hint | G3: VAF $ | H3: Devices | I3: Acc $
A4: 1 | B4: ='1'!Q16 -> 12 | C4: ='1'!R16 -> 6 | D4: ='1'!S16 -> 3 | E4: ='1'!T16 -> 4 | F4: ='1'!U16 -> 3 | G4: ='1'!V16 -> 319 | H4: ='1'!W16 -> 22 | I4: ='1'!X16 -> 1086.08
A5: 2 | B5: ='2'!Q16 -> 11 | C5: ='2'!R16 -> 5 | D5: ='2'!S16 -> 2 | E5: ='2'!T16 -> 1 | F5: ='2'!U16 -> 4 | G5: ='2'!V16 -> 248 | H5: ='2'!W16 -> 18 | I5: ='2'!X16 -> 1330.54
A6: 3 | B6: ='3'!Q16 -> 17 | C6: ='3'!R16 -> 6 | D6: ='3'!S16 -> 1 | E6: ='3'!T16 -> 0 | F6: ='3'!U16 -> 5 | G6: ='3'!V16 -> 273 | H6: ='3'!W16 -> 25 | I6: ='3'!X16 -> 1820.04
A7: 4 | B7: ='4'!Q16 -> 6 | C7: ='4'!R16 -> 4 | D7: ='4'!S16 -> 0 | E7: ='4'!T16 -> 1 | F7: ='4'!U16 -> 3 | G7: ='4'!V16 -> 225 | H7: ='4'!W16 -> 12 | I7: ='4'!X16 -> 816.73
A8: 5 | B8: ='5'!Q16 -> 24 | C8: ='5'!R16 -> 1 | D8: ='5'!S16 -> 0 | E8: ='5'!T16 -> 0 | F8: ='5'!U16 -> 2 | G8: ='5'!V16 -> 244 | H8: ='5'!W16 -> 26 | I8: ='5'!X16 -> 1902.31
A9: 6 | B9: ='6'!Q16 -> 8 | C9: ='6'!R16 -> 6 | D9: ='6'!S16 -> 0 | E9: ='6'!T16 -> 0 | F9: ='6'!U16 -> 3 | G9: ='6'!V16 -> 230 | H9: ='6'!W16 -> 16 | I9: ='6'!X16 -> 697.53
A10: 7 | B10: ='7'!Q16 -> 8 | C10: ='7'!R16 -> 1 | D10: ='7'!S16 -> 2 | E10: ='7'!T16 -> 6 | F10: ='7'!U16 -> 5 | G10: ='7'!V16 -> 165 | H10: ='7'!W16 -> 13 | I10: ='7'!X16 -> 784.43
A11: 8 | B11: ='8'!Q16 -> 16 | C11: ='8'!R16 -> 5 | D11: ='8'!S16 -> 1 | E11: ='8'!T16 -> 2 | F11: ='8'!U16 -> 5 | G11: ='8'!V16 -> 221 | H11: ='8'!W16 -> 22 | I11: ='8'!X16 -> 1660.33
A12: 9 | B12: ='9'!Q16 -> 13 | C12: ='9'!R16 -> 4 | D12: ='9'!S16 -> 2 | E12: ='9'!T16 -> 1 | F12: ='9'!U16 -> 2 | G12: ='9'!V16 -> 231 | H12: ='9'!W16 -> 20 | I12: ='9'!X16 -> 1250.13
A13: 10 | B13: ='10'!Q16 -> 12 | C13: ='10'!R16 -> 5 | D13: ='10'!S16 -> 0 | E13: ='10'!T16 -> 1 | F13: ='10'!U16 -> 1 | G13: ='10'!V16 -> 178 | H13: ='10'!W16 -> 21 | I13: ='10'!X16 -> 1735.11
A14: 11 | B14: ='11'!Q16 -> 9 | C14: ='11'!R16 -> 2 | D14: ='11'!S16 -> 0 | E14: ='11'!T16 -> 1 | F14: ='11'!U16 -> 2 | G14: ='11'!V16 -> 168 | H14: ='11'!W16 -> 15 | I14: ='11'!X16 -> 864.48
A15: 12 | B15: ='12'!Q16 -> 10 | C15: ='12'!R16 -> 8 | D15: ='12'!S16 -> 1 | E15: ='12'!T16 -> 0 | F15: ='12'!U16 -> 2 | G15: ='12'!V16 -> 202 | H15: ='12'!W16 -> 22 | I15: ='12'!X16 -> 734.84
A16: 13 | B16: ='13'!Q16 -> 21 | C16: ='13'!R16 -> 4 | D16: ='13'!S16 -> 3 | E16: ='13'!T16 -> 2 | F16: ='13'!U16 -> 1 | G16: ='13'!V16 -> 382 | H16: ='13'!W16 -> 29 | I16: ='13'!X16 -> 1089.65
A17: 14 | B17: ='14'!Q16 -> 16 | C17: ='14'!R16 -> 4 | D17: ='14'!S16 -> 2 | E17: ='14'!T16 -> 2 | F17: ='14'!U16 -> 2 | G17: ='14'!V16 -> 317 | H17: ='14'!W16 -> 26 | I17: ='14'!X16 -> 1811.69
A18: 15 | B18: ='15'!Q16 -> 10 | C18: ='15'!R16 -> 5 | D18: ='15'!S16 -> 2 | E18: ='15'!T16 -> 1 | F18: ='15'!U16 -> 2 | G18: ='15'!V16 -> 248 | H18: ='15'!W16 -> 22 | I18: ='15'!X16 -> 1503.79
A19: 16 | B19: ='16'!Q16 -> 17 | C19: ='16'!R16 -> 5 | D19: ='16'!S16 -> 1 | E19: ='16'!T16 -> 1 | F19: ='16'!U16 -> 3 | G19: ='16'!V16 -> 304 | H19: ='16'!W16 -> 27 | I19: ='16'!X16 -> 1458.04
A20: 17 | B20: ='17'!Q16 -> 9 | C20: ='17'!R16 -> 3 | D20: ='17'!S16 -> 3 | E20: ='17'!T16 -> 1 | F20: ='17'!U16 -> 4 | G20: ='17'!V16 -> 248 | H20: ='17'!W16 -> 19 | I20: ='17'!X16 -> 717.57
A21: 18 | B21: ='18'!Q16 -> 14 | C21: ='18'!R16 -> 10 | D21: ='18'!S16 -> 2 | E21: ='18'!T16 -> 1 | F21: ='18'!U16 -> 1 | G21: ='18'!V16 -> 238 | H21: ='18'!W16 -> 25 | I21: ='18'!X16 -> 1495.39
A22: 19 | B22: ='19'!Q16 -> 12 | C22: ='19'!R16 -> 4 | D22: ='19'!S16 -> 4 | E22: ='19'!T16 -> 0 | F22: ='19'!U16 -> 3 | G22: ='19'!V16 -> 450 | H22: ='19'!W16 -> 20 | I22: ='19'!X16 -> 1351.26
A23: 20 | B23: ='20'!Q16 -> 17 | C23: ='20'!R16 -> 5 | D23: ='20'!S16 -> 1 | E23: ='20'!T16 -> 0 | F23: ='20'!U16 -> 3 | G23: ='20'!V16 -> 354 | H23: ='20'!W16 -> 24 | I23: ='20'!X16 -> 1377.04
A24: 21 | B24: ='21'!Q16 -> 11 | C24: ='21'!R16 -> 6 | D24: ='21'!S16 -> 0 | E24: ='21'!T16 -> 1 | F24: ='21'!U16 -> 1 | G24: ='21'!V16 -> 263 | H24: ='21'!W16 -> 20 | I24: ='21'!X16 -> 1373.49
A25: 22 | B25: ='22'!Q16 -> 15 | C25: ='22'!R16 -> 6 | D25: ='22'!S16 -> 1 | E25: ='22'!T16 -> 2 | F25: ='22'!U16 -> 2 | G25: ='22'!V16 -> 265 | H25: ='22'!W16 -> 26 | I25: ='22'!X16 -> 2154.89
A26: 23 | B26: ='23'!Q16 -> 13 | C26: ='23'!R16 -> 1 | D26: ='23'!S16 -> 2 | E26: ='23'!T16 -> 4 | F26: ='23'!U16 -> 7 | G26: ='23'!V16 -> 268 | H26: ='23'!W16 -> 20 | I26: ='23'!X16 -> 1673.31
A27: 24 | B27: ='24'!Q16 -> 9 | C27: ='24'!R16 -> 6 | D27: ='24'!S16 -> 2 | E27: ='24'!T16 -> 1 | F27: ='24'!U16 -> 1 | G27: ='24'!V16 -> 193 | H27: ='24'!W16 -> 14 | I27: ='24'!X16 -> 487.68
A28: 25 | B28: ='25'!Q16 -> 8 | C28: ='25'!R16 -> 5 | D28: ='25'!S16 -> 2 | E28: ='25'!T16 -> 3 | F28: ='25'!U16 -> 2 | G28: ='25'!V16 -> 221 | H28: ='25'!W16 -> 17 | I28: ='25'!X16 -> 658.83
A29: 26 | B29: ='26'!Q16 -> 9 | C29: ='26'!R16 -> 5 | D29: ='26'!S16 -> 1 | E29: ='26'!T16 -> 0 | F29: ='26'!U16 -> 0 | G29: ='26'!V16 -> 137 | H29: ='26'!W16 -> 18 | I29: ='26'!X16 -> 868.06
A30: 27 | B30: ='27'!Q16 -> 5 | C30: ='27'!R16 -> 6 | D30: ='27'!S16 -> 1 | E30: ='27'!T16 -> 1 | F30: ='27'!U16 -> 2 | G30: ='27'!V16 -> 212 | H30: ='27'!W16 -> 18 | I30: ='27'!X16 -> 1041.57
A31: 28 | B31: ='28'!Q16 -> 14 | C31: ='28'!R16 -> 1 | D31: ='28'!S16 -> 1 | E31: ='28'!T16 -> 0 | F31: ='28'!U16 -> 1 | G31: ='28'!V16 -> 303 | H31: ='28'!W16 -> 22 | I31: ='28'!X16 -> 1539.67
A32: 29 | B32: ='29'!Q16 -> 12 | C32: ='29'!R16 -> 5 | D32: ='29'!S16 -> 0 | E32: ='29'!T16 -> 0 | F32: ='29'!U16 -> 3 | G32: ='29'!V16 -> 264 | H32: ='29'!W16 -> 19 | I32: ='29'!X16 -> 1176.17
A33: 30 | B33: ='30'!Q16 -> 8 | C33: ='30'!R16 -> 5 | D33: ='30'!S16 -> 1 | E33: ='30'!T16 -> 0 | F33: ='30'!U16 -> 1 | G33: ='30'!V16 -> 280 | H33: ='30'!W16 -> 20 | I33: ='30'!X16 -> 1506.37
A34: 31 | B34: ='31'!Q16 -> 15 | C34: ='31'!R16 -> 4 | D34: ='31'!S16 -> 1 | E34: ='31'!T16 -> 1 | F34: ='31'!U16 -> 0 | G34: ='31'!V16 -> 214 | H34: ='31'!W16 -> 17 | I34: ='31'!X16 -> 731.69

Sheet Store Total
A1: Store Total — month to date vs goal
A2: MOCK DATA — generated for portfolio use. No real employees, customers, device identifiers, or store numbers appear in this file.
A3: Metric | B3: Month Total | C3: Monthly Goal | D3: % to Goal | E3: vs Goal
A4: Acts | B4: =SUM('1:31'!Q16) -> 381 | C4: =Setup!$F$4 -> 365 | D4: =IFERROR(B4/C4,0) -> 1.0438356 | E4: =B4-C4 -> 16
A5: Pre | B5: =SUM('1:31'!R16) -> 143 | C5: =Setup!$F$5 -> 145 | D5: =IFERROR(B5/C5,0) -> 0.9862069 | E5: =B5-C5 -> -2
A6: TFB | B6: =SUM('1:31'!S16) -> 42 | C6: =Setup!$F$6 -> 40 | D6: =IFERROR(B6/C6,0) -> 1.05 | E6: =B6-C6 -> 2
A7: BTS | B7: =SUM('1:31'!T16) -> 38 | C7: =Setup!$F$7 -> 40 | D7: =IFERROR(B7/C7,0) -> 0.95 | E7: =B7-C7 -> -2
A8: Hint | B8: =SUM('1:31'!U16) -> 76 | C8: =Setup!$F$8 -> 75 | D8: =IFERROR(B8/C8,0) -> 1.0133333 | E8: =B8-C8 -> 1
A9: VAF $ | B9: =SUM('1:31'!V16) -> 7865 | C9: =Setup!$F$9 -> 7700 | D9: =IFERROR(B9/C9,0) -> 1.0214286 | E9: =B9-C9 -> 165
A10: Devices | B10: =SUM('1:31'!W16) -> 635 | C10: =Setup!$F$10 -> 600 | D10: =IFERROR(B10/C10,0) -> 1.0583333 | E10: =B10-C10 -> 35
A11: Acc $ | B11: =SUM('1:31'!X16) -> 38698.71 | C11: =Setup!$F$11 -> 39500 | D11: =IFERROR(B11/C11,0) -> 0.97971418 | E11: =B11-C11 -> -801.29

Sheet Setup
A1: Setup — edit these lists; every dropdown and roll-up follows them
A2: MOCK DATA — generated for portfolio use. No real employees, customers, device identifiers, or store numbers appear in this file.
A3: Mobile Experts | C3: Device Catalog | E3: Metric | F3: Monthly Goal
A4: Expert 01 | C4: iPhone 17 Pro Max | E4: Acts | F4: 365
A5: Expert 02 | C5: iPhone 17 Pro | E5: Pre | F5: 145
A6: Expert 03 | C6: iPhone 17 Air | E6: TFB | F6: 40
A7: Expert 04 | C7: iPhone 17 | E7: BTS | F7: 40
A8: Expert 05 | C8: iPad (11th Gen) | E8: Hint | F8: 75
A9: Expert 06 | C9: Apple Watch Series 11 | E9: VAF $ | F9: 7700
A10: Expert 07 | C10: Apple Watch SE | E10: Devices | F10: 600
A11: Expert 08 | C11: Apple Watch Ultra 3 | E11: Acc $ | F11: 39500
A12: Expert 09 | C12: Galaxy S26 Ultra
A13: Expert 10 | C13: Galaxy S26+
A14: Expert 11 | C14: Galaxy S26
A15: Expert 12 | C15: Galaxy Z Fold 7
C16: Galaxy Z Flip 7
C17: Galaxy A37
A18: Add or rename people in column A and devices in column C — the daily tabs pick the changes up automatically. Never type a device by hand; that is what broke the old sheet. | C18: Galaxy A17
C19: Galaxy Tab A11
C20: Galaxy Watch 8
C21: Pixel 10 Pro
C22: Pixel 10
C23: Pixel 10a
C24: moto g power
C25: 5G Home Internet Gateway
C26: 5G Hotspot
C27: SIM Only
C28: BYOD
C29: Accessory Only

Sheet 1
A1: Day 1 — Daily Entry
A2: MOCK DATA — generated for portfolio use. No real employees, customers, device identifiers, or store numbers appear in this file.
A3: ME | B3: SKU (mock) | C3: IMEI / SIM (mock) | D3: Device | E3: Acts | F3: Pre | G3: TFB | H3: BTS | I3: Hint | J3: VAF $ | K3: Devices | L3: Acc $ | M3: Complete | P3: Mobile Expert | Q3: Acts | R3: Pre | S3: TFB | T3: BTS | U3: Hint | V3: VAF $ | W3: Devices | X3: Acc $
A4: Expert 01 | B4: SKU-7148 | C4: MOCK-926629 | D4: moto g power | E4: 0 | F4: 1 | G4: 0 | H4: 0 | I4: 0 | J4: 24 | K4: 1 | L4: 176.07 | M4: Y | P4: =Setup!$A$4 -> Expert 01 | Q4: =SUMIF($A$4:$A$43,$P4,E$4:E$43) -> 0 | R4: =SUMIF($A$4:$A$43,$P4,F$4:F$43) -> 2 | S4: =SUMIF($A$4:$A$43,$P4,G$4:G$43) -> 0 | T4: =SUMIF($A$4:$A$43,$P4,H$4:H$43) -> 1 | U4: =SUMIF($A$4:$A$43,$P4,I$4:I$43) -> 1 | V4: =SUMIF($A$4:$A$43,$P4,J$4:J$43) -> 73 | W4: =SUMIF($A$4:$A$43,$P4,K$4:K$43) -> 4 | X4: =SUMIF($A$4:$A$43,$P4,L$4:L$43) -> 373.14
A5: Expert 12 | B5: SKU-4615 | C5: MOCK-140093 | D5: Galaxy Watch 8 | E5: 0 | F5: 1 | G5: 0 | H5: 0 | I5: 0 | J5: 33 | K5: 1 | L5: 102.47 | M5: Y | P5: =Setup!$A$5 -> Expert 02 | Q5: =SUMIF($A$4:$A$43,$P5,E$4:E$43) -> 3 | R5: =SUMIF($A$4:$A$43,$P5,F$4:F$43) -> 0 | S5: =SUMIF($A$4:$A$43,$P5,G$4:G$43) -> 0 | T5: =SUMIF($A$4:$A$43,$P5,H$4:H$43) -> 0 | U5: =SUMIF($A$4:$A$43,$P5,I$4:I$43) -> 0 | V5: =SUMIF($A$4:$A$43,$P5,J$4:J$43) -> 18 | W5: =SUMIF($A$4:$A$43,$P5,K$4:K$43) -> 4 | X5: =SUMIF($A$4:$A$43,$P5,L$4:L$43) -> 85.85
A6: Expert 04 | B6: SKU-2399 | C6: MOCK-837234 | D6: Apple Watch Ultra 3 | E6: 1 | F6: 0 | G6: 0 | H6: 0 | I6: 0 | J6: 0 | K6: 1 | L6: 0 | M6: Y | P6: =Setup!$A$6 -> Expert 03 | Q6: =SUMIF($A$4:$A$43,$P6,E$4:E$43) -> 1 | R6: =SUMIF($A$4:$A$43,$P6,F$4:F$43) -> 0 | S6: =SUMIF($A$4:$A$43,$P6,G$4:G$43) -> 0 | T6: =SUMIF($A$4:$A$43,$P6,H$4:H$43) -> 0 | U6: =SUMIF($A$4:$A$43,$P6,I$4:I$43) -> 0 | V6: =SUMIF($A$4:$A$43,$P6,J$4:J$43) -> 0 | W6: =SUMIF($A$4:$A$43,$P6,K$4:K$43) -> 1 | X6: =SUMIF($A$4:$A$43,$P6,L$4:L$43) -> 160.78
A7: Expert 12 | B7: SKU-6283 | C7: MOCK-307883 | D7: BYOD | E7: 0 | F7: 1 | G7: 1 | H7: 0 | I7: 0 | J7: 18 | K7: 0 | L7: 0 | M7: Y | P7: =Setup!$A$7 -> Expert 04 | Q7: =SUMIF($A$4:$A$43,$P7,E$4:E$43) -> 3 | R7: =SUMIF($A$4:$A$43,$P7,F$4:F$43) -> 0 | S7: =SUMIF($A$4:$A$43,$P7,G$4:G$43) -> 0 | T7: =SUMIF($A$4:$A$43,$P7,H$4:H$43) -> 1 | U7: =SUMIF($A$4:$A$43,$P7,I$4:I$43) -> 0 | V7: =SUMIF($A$4:$A$43,$P7,J$4:J$43) -> 34 | W7: =SUMIF($A$4:$A$43,$P7,K$4:K$43) -> 4 | X7: =SUMIF($A$4:$A$43,$P7,L$4:L$43) -> 58.48
A8: Expert 02 | B8: SKU-6239 | C8: MOCK-334994 | D8: Galaxy S26+ | E8: 1 | F8: 0 | G8: 0 | H8: 0 | I8: 0 | J8: 0 | K8: 1 | L8: 59.14 | M8: Y | P8: =Setup!$A$8 -> Expert 05 | Q8: =SUMIF($A$4:$A$43,$P8,E$4:E$43) -> 0 | R8: =SUMIF($A$4:$A$43,$P8,F$4:F$43) -> 0 | S8: =SUMIF($A$4:$A$43,$P8,G$4:G$43) -> 0 | T8: =SUMIF($A$4:$A$43,$P8,H$4:H$43) -> 0 | U8: =SUMIF($A$4:$A$43,$P8,I$4:I$43) -> 0 | V8: =SUMIF($A$4:$A$43,$P8,J$4:J$43) -> 0 | W8: =SUMIF($A$4:$A$43,$P8,K$4:K$43) -> 0 | X8: =SUMIF($A$4:$A$43,$P8,L$4:L$43) -> 0
A9: Expert 07 | B9: SKU-4410 | C9: MOCK-995961 | D9: Galaxy A17 | E9: 1 | F9: 0 | G9: 0 | H9: 0 | I9: 0 | J9: 16 | K9: 1 | L9: 17.02 | M9: Y | P9: =Setup!$A$9 -> Expert 06 | Q9: =SUMIF($A$4:$A$43,$P9,E$4:E$43) -> 0 | R9: =SUMIF($A$4:$A$43,$P9,F$4:F$43) -> 0 | S9: =SUMIF($A$4:$A$43,$P9,G$4:G$43) -> 0 | T9: =SUMIF($A$4:$A$43,$P9,H$4:H$43) -> 0 | U9: =SUMIF($A$4:$A$43,$P9,I$4:I$43) -> 0 | V9: =SUMIF($A$4:$A$43,$P9,J$4:J$43) -> 0 | W9: =SUMIF($A$4:$A$43,$P9,K$4:K$43) -> 0 | X9: =SUMIF($A$4:$A$43,$P9,L$4:L$43) -> 124.51
A10: Expert 02 | B10: SKU-4412 | C10: MOCK-648891 | D10: Pixel 10 | E10: 0 | F10: 0 | G10: 0 | H10: 0 | I10: 0 | J10: 0 | K10: 1 | L10: 0 | M10: Y | P10: =Setup!$A$10 -> Expert 07 | Q10: =SUMIF($A$4:$A$43,$P10,E$4:E$43) -> 1 | R10: =SUMIF($A$4:$A$43,$P10,F$4:F$43) -> 0 | S10: =SUMIF($A$4:$A$43,$P10,G$4:G$43) -> 0 | T10: =SUMIF($A$4:$A$43,$P10,H$4:H$43) -> 0 | U10: =SUMIF($A$4:$A$43,$P10,I$4:I$43) -> 0 | V10: =SUMIF($A$4:$A$43,$P10,J$4:J$43) -> 16 | W10: =SUMIF($A$4:$A$43,$P10,K$4:K$43) -> 1 | X10: =SUMIF($A$4:$A$43,$P10,L$4:L$43) -> 17.02
A11: Expert 04 | B11: SKU-7107 | C11: MOCK-483314 | D11: Pixel 10a | E11: 0 | F11: 0 | G11: 0 | H11: 0 | I11: 0 | J11: 16 | K11: 1 | L11: 0 | M11: Y | P11: =Setup!$A$11 -> Expert 08 | Q11: =SUMIF($A$4:$A$43,$P11,E$4:E$43) -> 1 | R11: =SUMIF($A$4:$A$43,$P11,F$4:F$43) -> 0 | S11: =SUMIF($A$4:$A$43,$P11,G$4:G$43) -> 1 | T11: =SUMIF($A$4:$A$43,$P11,H$4:H$43) -> 0 | U11: =SUMIF($A$4:$A$43,$P11,I$4:I$43) -> 0 | V11: =SUMIF($A$4:$A$43,$P11,J$4:J$43) -> 24 | W11: =SUMIF($A$4:$A$43,$P11,K$4:K$43) -> 1 | X11: =SUMIF($A$4:$A$43,$P11,L$4:L$43) -> 0
A12: Expert 06 | B12: SKU-7381 | C12: MOCK-967923 | D12: BYOD | E12: 0 | F12: 0 | G12: 0 | H12: 0 | I12: 0 | J12: 0 | K12: 0 | L12: 124.51 | M12: Y | P12: =Setup!$A$12 -> Expert 09 | Q12: =SUMIF($A$4:$A$43,$P12,E$4:E$43) -> 1 | R12: =SUMIF($A$4:$A$43,$P12,F$4:F$43) -> 0 | S12: =SUMIF($A$4:$A$43,$P12,G$4:G$43) -> 0 | T12: =SUMIF($A$4:$A$43,$P12,H$4:H$43) -> 0 | U12: =SUMIF($A$4:$A$43,$P12,I$4:I$43) -> 0 | V12: =SUMIF($A$4:$A$43,$P12,J$4:J$43) -> 24 | W12: =SUMIF($A$4:$A$43,$P12,K$4:K$43) -> 1 | X12: =SUMIF($A$4:$A$43,$P12,L$4:L$43) -> 0
A13: Expert 02 | B13: SKU-2226 | C13: MOCK-890465 | D13: Galaxy A17 | E13: 1 | F13: 0 | G13: 0 | H13: 0 | I13: 0 | J13: 0 | K13: 1 | L13: 0 | M13: Y | P13: =Setup!$A$13 -> Expert 10 | Q13: =SUMIF($A$4:$A$43,$P13,E$4:E$43) -> 1 | R13: =SUMIF($A$4:$A$43,$P13,F$4:F$43) -> 0 | S13: =SUMIF($A$4:$A$43,$P13,G$4:G$43) -> 0 | T13: =SUMIF($A$4:$A$43,$P13,H$4:H$43) -> 0 | U13: =SUMIF($A$4:$A$43,$P13,I$4:I$43) -> 0 | V13: =SUMIF($A$4:$A$43,$P13,J$4:J$43) -> 0 | W13: =SUMIF($A$4:$A$43,$P13,K$4:K$43) -> 1 | X13: =SUMIF($A$4:$A$43,$P13,L$4:L$43) -> 0
A14: Expert 11 | B14: SKU-2548 | C14: MOCK-738205 | D14: Apple Watch Ultra 3 | E14: 0 | F14: 1 | G14: 0 | H14: 0 | I14: 0 | J14: 33 | K14: 1 | L14: 38.33 | M14: Y | P14: =Setup!$A$14 -> Expert 11 | Q14: =SUMIF($A$4:$A$43,$P14,E$4:E$43) -> 0 | R14: =SUMIF($A$4:$A$43,$P14,F$4:F$43) -> 2 | S14: =SUMIF($A$4:$A$43,$P14,G$4:G$43) -> 1 | T14: =SUMIF($A$4:$A$43,$P14,H$4:H$43) -> 1 | U14: =SUMIF($A$4:$A$43,$P14,I$4:I$43) -> 1 | V14: =SUMIF($A$4:$A$43,$P14,J$4:J$43) -> 63 | W14: =SUMIF($A$4:$A$43,$P14,K$4:K$43) -> 3 | X14: =SUMIF($A$4:$A$43,$P14,L$4:L$43) -> 140.99
A15: Expert 02 | B15: SKU-1653 | C15: MOCK-206689 | D15: iPhone 17 | E15: 1 | F15: 0 | G15: 0 | H15: 0 | I15: 0 | J15: 18 | K15: 1 | L15: 26.71 | M15: Y | P15: =Setup!$A$15 -> Expert 12 | Q15: =SUMIF($A$4:$A$43,$P15,E$4:E$43) -> 1 | R15: =SUMIF($A$4:$A$43,$P15,F$4:F$43) -> 2 | S15: =SUMIF($A$4:$A$43,$P15,G$4:G$43) -> 1 | T15: =SUMIF($A$4:$A$43,$P15,H$4:H$43) -> 1 | U15: =SUMIF($A$4:$A$43,$P15,I$4:I$43) -> 1 | V15: =SUMIF($A$4:$A$43,$P15,J$4:J$43) -> 67 | W15: =SUMIF($A$4:$A$43,$P15,K$4:K$43) -> 2 | X15: =SUMIF($A$4:$A$43,$P15,L$4:L$43) -> 125.31
A16: Expert 01 | B16: SKU-7882 | C16: MOCK-373803 | D16: Galaxy Watch 8 | E16: 0 | F16: 0 | G16: 0 | H16: 0 | I16: 0 | J16: 0 | K16: 1 | L16: 165.58 | M16: N | P16: STORE TOTAL | Q16: =SUM(Q4:Q15) -> 12 | R16: =SUM(R4:R15) -> 6 | S16: =SUM(S4:S15) -> 3 | T16: =SUM(T4:T15) -> 4 | U16: =SUM(U4:U15) -> 3 | V16: =SUM(V4:V15) -> 319 | W16: =SUM(W4:W15) -> 22 | X16: =SUM(X4:X15) -> 1086.08
A17: Expert 01 | B17: SKU-7914 | C17: MOCK-801671 | D17: Galaxy S26+ | E17: 0 | F17: 1 | G17: 0 | H17: 1 | I17: 0 | J17: 16 | K17: 1 | L17: 0 | M17: Y
A18: Expert 11 | B18: SKU-8389 | C18: MOCK-108383 | D18: Galaxy S26+ | E18: 0 | F18: 0 | G18: 0 | H18: 0 | I18: 0 | J18: 15 | K18: 1 | L18: 102.66 | M18: Y
A19: Expert 03 | B19: SKU-1548 | C19: MOCK-401291 | D19: Galaxy S26 | E19: 1 | F19: 0 | G19: 0 | H19: 0 | I19: 0 | J19: 0 | K19: 1 | L19: 160.78 | M19: Y
A20: Expert 12 | B20: SKU-5729 | C20: MOCK-407822 | D20: 5G Home Internet Gateway | E20: 0 | F20: 0 | G20: 0 | H20: 0 | I20: 1 | J20: 0 | K20: 0 | L20: 0 | M20: Y
A21: Expert 10 | B21: SKU-4801 | C21: MOCK-937364 | D21: Galaxy Z Flip 7 | E21: 1 | F21: 0 | G21: 0 | H21: 0 | I21: 0 | J21: 0 | K21: 1 | L21: 0 | M21: Y
A22: Expert 04 | B22: SKU-8275 | C22: MOCK-627721 | D22: Apple Watch Series 11 | E22: 1 | F22: 0 | G22: 0 | H22: 1 | I22: 0 | J22: 18 | K22: 1 | L22: 58.48 | M22: Y
A23: Expert 11 | B23: SKU-7137 | C23: MOCK-580944 | D23: 5G Hotspot | E23: 0 | F23: 0 | G23: 1 | H23: 1 | I23: 1 | J23: 15 | K23: 0 | L23: 0 | M23: Y
A24: Expert 08 | B24: SKU-1658 | C24: MOCK-991136 | D24: Galaxy S26 Ultra | E24: 1 | F24: 0 | G24: 1 | H24: 0 | I24: 0 | J24: 24 | K24: 1 | L24: 0 | M24: Y
A25: Expert 09 | B25: SKU-8902 | C25: MOCK-221411 | D25: iPhone 17 Pro Max | E25: 1 | F25: 0 | G25: 0 | H25: 0 | I25: 0 | J25: 24 | K25: 1 | L25: 0 | M25: Y
A26: Expert 12 | B26: SKU-2453 | C26: MOCK-269140 | D26: Galaxy A17 | E26: 1 | F26: 0 | G26: 0 | H26: 1 | I26: 0 | J26: 16 | K26: 1 | L26: 22.84 | M26: Y
A27: Expert 01 | B27: SKU-2758 | C27: MOCK-572529 | D27: Galaxy A17 | E27: 0 | F27: 0 | G27: 0 | H27: 0 | I27: 0 | J27: 33 | K27: 1 | L27: 0 | M27: Y
A28: Expert 01 | B28: SKU-9094 | C28: MOCK-674744 | D28: 5G Hotspot | E28: 0 | F28: 0 | G28: 0 | H28: 0 | I28: 1 | J28: 0 | K28: 0 | L28: 31.49 | M28: Y
... A30: Expert 11 | B30: SKU-6346 | C30: MOCK-465247 | D30: Pixel 10a | E30: 0 | F30: 1 | G30: 0 | H30: 0 | I30: 0 | J30: 0 | K30: 1 | L30: 0 | M30: Y

Sheet 2
A1: Day 2 — Daily Entry
A2: MOCK DATA — generated for portfolio use. No real employees, customers, device identifiers, or store numbers appear in this file.
A3: ME | B3: SKU (mock) | C3: IMEI / SIM (mock) | D3: Device | E3: Acts | F3: Pre | G3: TFB | H3: BTS | I3: Hint | J3: VAF $ | K3: Devices | L3: Acc $ | M3: Complete | P3: Mobile Expert | Q3: Acts | R3: Pre | S3: TFB | T3: BTS | U3: Hint | V3: VAF $ | W3: Devices | X3: Acc $
A4: Expert 02 | B4: SKU-8476 | C4: MOCK-567258 | D4: iPad (11th Gen) | E4: 1 | F4: 0 | G4: 0 | H4: 0 | I4: 0 | J4: 0 | K4: 1 | L4: 104.31 | M4: Y | P4: =Setup!$A$4 -> Expert 01 | Q4: =SUMIF($A$4:$A$43,$P4,E$4:E$43) -> 1 | R4: =SUMIF($A$4:$A$43,$P4,F$4:F$43) -> 0 | S4: =SUMIF($A$4:$A$43,$P4,G$4:G$43) -> 0 | T4: =SUMIF($A$4:$A$43,$P4,H$4:H$43) -> 0 | U4: =SUMIF($A$4:$A$43,$P4,I$4:I$43) -> 0 | V4: =SUMIF($A$4:$A$43,$P4,J$4:J$43) -> 18 | W4: =SUMIF($A$4:$A$43,$P4,K$4:K$43) -> 2 | X4: =SUMIF($A$4:$A$43,$P4,L$4:L$43) -> 99.5
A5: Expert 02 | B5: SKU-9943 | C5: MOCK-815524 | D5: iPhone 17 Air | E5: 0 | F5: 0 | G5: 0 | H5: 0 | I5: 0 | J5: 15 | K5: 1 | L5: 0 | M5: Y | P5: =Setup!$A$5 -> Expert 02 | Q5: =SUMIF($A$4:$A$43,$P5,E$4:E$43) -> 3 | R5: =SUMIF($A$4:$A$43,$P5,F$4:F$43) -> 0 | S5: =SUMIF($A$4:$A$43,$P5,G$4:G$43) -> 1 | T5: =SUMIF($A$4:$A$43,$P5,H$4:H$43) -> 1 | U5: =SUMIF($A$4:$A$43,$P5,I$4:I$43) -> 0 | V5: =SUMIF($A$4:$A$43,$P5,J$4:J$43) -> 48 | W5: =SUMIF($A$4:$A$43,$P5,K$4:K$43) -> 4 | X5: =SUMIF($A$4:$A$43,$P5,L$4:L$43) -> 217.4
A6: Expert 06 | B6: SKU-4472 | C6: MOCK-836100 | D6: 5G Hotspot | E6: 0 | F6: 0 | G6: 0 | H6: 0 | I6: 1 | J6: 0 | K6: 0 | L6: 0 | M6: Y | P6: =Setup!$A$6 -> Expert 03 | Q6: =SUMIF($A$4:$A$43,$P6,E$4:E$43) -> 0 | R6: =SUMIF($A$4:$A$43,$P6,F$4:F$43) -> 0 | S6: =SUMIF($A$4:$A$43,$P6,G$4:G$43) -> 0 | T6: =SUMIF($A$4:$A$43,$P6,H$4:H$43) -> 0 | U6: =SUMIF($A$4:$A$43,$P6,I$4:I$43) -> 0 | V6: =SUMIF($A$4:$A$43,$P6,J$4:J$43) -> 0 | W6: =SUMIF($A$4:$A$43,$P6,K$4:K$43) -> 0 | X6: =SUMIF($A$4:$A$43,$P6,L$4:L$43) -> 0
A7: Expert 07 | B7: SKU-1114 | C7: MOCK-336279 | D7: Galaxy Z Flip 7 | E7: 0 | F7: 0 | G7: 0 | H7: 0 | I7: 0 | J7: 33 | K7: 1 | L7: 0 | M7: Y | P7: =Setup!$A$7 -> Expert 04 | Q7: =SUMIF($A$4:$A$43,$P7,E$4:E$43) -> 0 | R7: =SUMIF($A$4:$A$43,$P7,F$4:F$43) -> 0 | S7: =SUMIF($A$4:$A$43,$P7,G$4:G$43) -> 0 | T7: =SUMIF($A$4:$A$43,$P7,H$4:H$43) -> 0 | U7: =SUMIF($A$4:$A$43,$P7,I$4:I$43) -> 0 | V7: =SUMIF($A$4:$A$43,$P7,J$4:J$43) -> 0 | W7: =SUMIF($A$4:$A$43,$P7,K$4:K$43) -> 0 | X7: =SUMIF($A$4:$A$43,$P7,L$4:L$43) -> 0
A8: Expert 10 | B8: SKU-4933 | C8: MOCK-517548 | D8: Galaxy Tab A11 | E8: 1 | F8: 0 | G8: 0 | H8: 0 | I8: 0 | J8: 0 | K8: 1 | L8: 0 | M8: Y | P8: =Setup!$A$8 -> Expert 05 | Q8: =SUMIF($A$4:$A$43,$P8,E$4:E$43) -> 2 | R8: =SUMIF($A$4:$A$43,$P8,F$4:F$43) -> 3 | S8: =SUMIF($A$4:$A$43,$P8,G$4:G$43) -> 0 | T8: =SUMIF($A$4:$A$43,$P8,H$4:H$43) -> 0 | U8: =SUMIF($A$4:$A$43,$P8,I$4:I$43) -> 0 | V8: =SUMIF($A$4:$A$43,$P8,J$4:J$43) -> 57 | W8: =SUMIF($A$4:$A$43,$P8,K$4:K$43) -> 5 | X8: =SUMIF($A$4:$A$43,$P8,L$4:L$43) -> 381.37
A9: Expert 05 | B9: SKU-6153 | C9: MOCK-348615 | D9: Galaxy S26 Ultra | E9: 1 | F9: 0 | G9: 0 | H9: 0 | I9: 0 | J9: 24 | K9: 1 | L9: 115.27 | M9: Y | P9: =Setup!$A$9 -> Expert 06 | Q9: =SUMIF($A$4:$A$43,$P9,E$4:E$43) -> 0 | R9: =SUMIF($A$4:$A$43,$P9,F$4:F$43) -> 2 | S9: =SUMIF($A$4:$A$43,$P9,G$4:G$43) -> 0 | T9: =SUMIF($A$4:$A$43,$P9,H$4:H$43) -> 0 | U9: =SUMIF($A$4:$A$43,$P9,I$4:I$43) -> 2 | V9: =SUMIF($A$4:$A$43,$P9,J$4:J$43) -> 15 | W9: =SUMIF($A$4:$A$43,$P9,K$4:K$43) -> 1 | X9: =SUMIF($A$4:$A$43,$P9,L$4:L$43) -> 212.92
A10: Expert 01 | B10: SKU-8525 | C10: MOCK-961726 | D10: iPhone 17 Air | E10: 1 | F10: 0 | G10: 0 | H10: 0 | I10: 0 | J10: 18 | K10: 1 | L10: 99.5 | M10: Y | P10: =Setup!$A$10 -> Expert 07 | Q10: =SUMIF($A$4:$A$43,$P10,E$4:E$43) -> 0 | R10: =SUMIF($A$4:$A$43,$P10,F$4:F$43) -> 0 | S10: =SUMIF($A$4:$A$43,$P10,G$4:G$43) -> 0 | T10: =SUMIF($A$4:$A$43,$P10,H$4:H$43) -> 0 | U10: =SUMIF($A$4:$A$43,$P10,I$4:I$43) -> 0 | V10: =SUMIF($A$4:$A$43,$P10,J$4:J$43) -> 33 | W10: =SUMIF($A$4:$A$43,$P10,K$4:K$43) -> 1 | X10: =SUMIF($A$4:$A$43,$P10,L$4:L$43) -> 0
A11: Expert 11 | B11: SKU-9015 | C11: MOCK-426151 | D11: 5G Hotspot | E11: 0 | F11: 0 | G11: 1 | H11: 0 | I11: 1 | J11: 16 | K11: 0 | L11: 56.26 | M11: Y | P11: =Setup!$A$11 -> Expert 08 | Q11: =SUMIF($A$4:$A$43,$P11,E$4:E$43) -> 1 | R11: =SUMIF($A$4:$A$43,$P11,F$4:F$43) -> 0 | S11: =SUMIF($A$4:$A$43,$P11,G$4:G$43) -> 0 | T11: =SUMIF($A$4:$A$43,$P11,H$4:H$43) -> 0 | U11: =SUMIF($A$4:$A$43,$P11,I$4:I$43) -> 0 | V11: =SUMIF($A$4:$A$43,$P11,J$4:J$43) -> 31 | W11: =SUMIF($A$4:$A$43,$P11,K$4:K$43) -> 1 | X11: =SUMIF($A$4:$A$43,$P11,L$4:L$43) -> 94.91
A12: Expert 05 | B12: SKU-9886 | C12: MOCK-227133 | D12: iPhone 17 Pro Max | E12: 1 | F12: 0 | G12: 0 | H12: 0 | I12: 0 | J12: 0 | K12: 1 | L12: 96.5 | M12: Y | P12: =Setup!$A$12 -> Expert 09 | Q12: =SUMIF($A$4:$A$43,$P12,E$4:E$43) -> 0 | R12: =SUMIF($A$4:$A$43,$P12,F$4:F$43) -> 0 | S12: =SUMIF($A$4:$A$43,$P12,G$4:G$43) -> 0 | T12: =SUMIF($A$4:$A$43,$P12,H$4:H$43) -> 0 | U12: =SUMIF($A$4:$A$43,$P12,I$4:I$43) -> 0 | V12: =SUMIF($A$4:$A$43,$P12,J$4:J$43) -> 0 | W12: =SUMIF($A$4:$A$43,$P12,K$4:K$43) -> 0 | X12: =SUMIF($A$4:$A$43,$P12,L$4:L$43) -> 0
A13: Expert 05 | B13: SKU-6521 | C13: MOCK-613709 | D13: Galaxy A17 | E13: 0 | F13: 1 | G13: 0 | H13: 0 | I13: 0 | J13: 0 | K13: 1 | L13: 81.93 | M13: Y | P13: =Setup!$A$13 -> Expert 10 | Q13: =SUMIF($A$4:$A$43,$P13,E$4:E$43) -> 4 | R13: =SUMIF($A$4:$A$43,$P13,F$4:F$43) -> 0 | S13: =SUMIF($A$4:$A$43,$P13,G$4:G$43) -> 0 | T13: =SUMIF($A$4:$A$43,$P13,H$4:H$43) -> 0 | U13: =SUMIF($A$4:$A$43,$P13,I$4:I$43) -> 1 | V13: =SUMIF($A$4:$A$43,$P13,J$4:J$43) -> 30 | W13: =SUMIF($A$4:$A$43,$P13,K$4:K$43) -> 4 | X13: =SUMIF($A$4:$A$43,$P13,L$4:L$43) -> 268.18
A14: Expert 08 | B14: SKU-5464 | C14: MOCK-939388 | D14: SIM Only | E14: 1 | F14: 0 | G14: 0 | H14: 0 | I14: 0 | J14: 16 | K14: 0 | L14: 0 | M14: Y | P14: =Setup!$A$14 -> Expert 11 | Q14: =SUMIF($A$4:$A$43,$P14,E$4:E$43) -> 0 | R14: =SUMIF($A$4:$A$43,$P14,F$4:F$43) -> 0 | S14: =SUMIF($A$4:$A$43,$P14,G$4:G$43) -> 1 | T14: =SUMIF($A$4:$A$43,$P14,H$4:H$43) -> 0 | U14: =SUMIF($A$4:$A$43,$P14,I$4:I$43) -> 1 | V14: =SUMIF($A$4:$A$43,$P14,J$4:J$43) -> 16 | W14: =SUMIF($A$4:$A$43,$P14,K$4:K$43) -> 0 | X14: =SUMIF($A$4:$A$43,$P14,L$4:L$43) -> 56.26
A15: Expert 10 | B15: SKU-7076 | C15: MOCK-855141 | D15: 5G Hotspot | E15: 0 | F15: 0 | G15: 0 | H15: 0 | I15: 1 | J15: 0 | K15: 0 | L15: 177.44 | M15: Y | P15: =Setup!$A$15 -> Expert 12 | Q15: =SUMIF($A$4:$A$43,$P15,E$4:E$43) -> 0 | R15: =SUMIF($A$4:$A$43,$P15,F$4:F$43) -> 0 | S15: =SUMIF($A$4:$A$43,$P15,G$4:G$43) -> 0 | T15: =SUMIF($A$4:$A$43,$P15,H$4:H$43) -> 0 | U15: =SUMIF($A$4:$A$43,$P15,I$4:I$43) -> 0 | V15: =SUMIF($A$4:$A$43,$P15,J$4:J$43) -> 0 | W15: =SUMIF($A$4:$A$43,$P15,K$4:K$43) -> 0 | X15: =SUMIF($A$4:$A$43,$P15,L$4:L$43) -> 0
A16: Expert 06 | B16: SKU-1480 | C16: MOCK-755871 | D16: Galaxy S26+ | E16: 0 | F16: 1 | G16: 0 | H16: 0 | I16: 0 | J16: 15 | K16: 1 | L16: 167.85 | M16: Y | P16: STORE TOTAL | Q16: =SUM(Q4:Q15) -> 11 | R16: =SUM(R4:R15) -> 5 | S16: =SUM(S4:S15) -> 2 | T16: =SUM(T4:T15) -> 1 | U16: =SUM(U4:U15) -> 4 | V16: =SUM(V4:V15) -> 248 | W16: =SUM(W4:W15) -> 18 | X16: =SUM(X4:X15) -> 1330.54
A17: Expert 05 | B17: SKU-9121 | C17: MOCK-689871 | D17: Galaxy A37 | E17: 0 | F17: 1 | G17: 0 | H17: 0 | I17: 0 | J17: 33 | K17: 1 | L17: 87.67 | M17: Y
A18: Expert 02 | B18: SKU-5468 | C18: MOCK-488724 | D18: Galaxy A37 | E18: 1 | F18: 0 | G18: 1 | H18: 0 | I18: 0 | J18: 0 | K18: 1 | L18: 113.09 | M18: Y
A19: Expert 05 | B19: SKU-7337 | C19: MOCK-545522 | D19: Galaxy A17 | E19: 0 | F19: 1 | G19: 0 | H19: 0 | I19: 0 | J19: 0 | K19: 1 | L19: 0 | M19: Y
A20: Expert 10 | B20: SKU-9810 | C20: MOCK-187619 | D20: Galaxy S26+ | E20: 1 | F20: 0 | G20: 0 | H20: 0 | I20: 0 | J20: 15 | K20: 1 | L20: 90.74 | M20: Y
A21: Expert 01 | B21: SKU-7087 | C21: MOCK-546338 | D21: iPhone 17 Air | E21: 0 | F21: 0 | G21: 0 | H21: 0 | I21: 0 | J21: 0 | K21: 1 | L21: 0 | M21: N
A22: Expert 10 | B22: SKU-6585 | C22: MOCK-417604 | D22: Apple Watch SE | E22: 1 | F22: 0 | G22: 0 | H22: 0 | I22: 0 | J22: 0 | K22: 1 | L22: 0 | M22: Y
A23: Expert 10 | B23: SKU-8072 | C23: MOCK-705283 | D23: Galaxy S26 Ultra | E23: 1 | F23: 0 | G23: 0 | H23: 0 | I23: 0 | J23: 15 | K23: 1 | L23: 0 | M23: Y
A24: Expert 02 | B24: SKU-3152 | C24: MOCK-721608 | D24: Galaxy Z Fold 7 | E24: 1 | F24: 0 | G24: 0 | H24: 1 | I24: 0 | J24: 33 | K24: 1 | L24: 0 | M24: Y
A25: Expert 06 | B25: SKU-3733 | C25: MOCK-221851 | D25: 5G Home Internet Gateway | E25: 0 | F25: 1 | G25: 0 | H25: 0 | I25: 1 | J25: 0 | K25: 0 | L25: 45.07 | M25: Y
A26: Expert 08 | B26: SKU-1740 | C26: MOCK-511237 | D26: Galaxy S26+ | E26: 0 | F26: 0 | G26: 0 | H26: 0 | I26: 0 | J26: 15 | K26: 1 | L26: 94.91 | M26: Y

Sheet 3
A1: Day 3 — Daily Entry
A2: MOCK DATA — generated for portfolio use. No real employees, customers, device identifiers, or store numbers appear in this file.
A3: ME | B3: SKU (mock) | C3: IMEI / SIM (mock) | D3: Device | E3: Acts | F3: Pre | G3: TFB | H3: BTS | I3: Hint | J3: VAF $ | K3: Devices | L3: Acc $ | M3: Complete | P3: Mobile Expert | Q3: Acts | R3: Pre | S3: TFB | T3: BTS | U3: Hint | V3: VAF $ | W3: Devices | X3: Acc $
A4: Expert 06 | B4: SKU-6334 | C4: MOCK-190905 | D4: moto g power | E4: 1 | F4: 0 | G4: 0 | H4: 0 | I4: 0 | J4: 0 | K4: 1 | L4: 140.14 | M4: Y | P4: =Setup!$A$4 -> Expert 01 | Q4: =SUMIF($A$4:$A$43,$P4,E$4:E$43) -> 1 | R4: =SUMIF($A$4:$A$43,$P4,F$4:F$43) -> 0 | S4: =SUMIF($A$4:$A$43,$P4,G$4:G$43) -> 0 | T4: =SUMIF($A$4:$A$43,$P4,H$4:H$43) -> 0 | U4: =SUMIF($A$4:$A$43,$P4,I$4:I$43) -> 0 | V4: =SUMIF($A$4:$A$43,$P4,J$4:J$43) -> 0 | W4: =SUMIF($A$4:$A$43,$P4,K$4:K$43) -> 1 | X4: =SUMIF($A$4:$A$43,$P4,L$4:L$43) -> 8.62
A5: Expert 11 | B5: SKU-9300 | C5: MOCK-855774 | D5: Apple Watch SE | E5: 1 | F5: 0 | G5: 0 | H5: 0 | I5: 0 | J5: 0 | K5: 1 | L5: 74.81 | M5: Y | P5: =Setup!$A$5 -> Expert 02 | Q5: =SUMIF($A$4:$A$43,$P5,E$4:E$43) -> 3 | R5: =SUMIF($A$4:$A$43,$P5,F$4:F$43) -> 2 | S5: =SUMIF($A$4:$A$43,$P5,G$4:G$43) -> 0 | T5: =SUMIF($A$4:$A$43,$P5,H$4:H$43) -> 0 | U5: =SUMIF($A$4:$A$43,$P5,I$4:I$43) -> 1 | V5: =SUMIF($A$4:$A$43,$P5,J$4:J$43) -> 51 | W5: =SUMIF($A$4:$A$43,$P5,K$4:K$43) -> 3 | X5: =SUMIF($A$4:$A$43,$P5,L$4:L$43) -> 237.97
A6: Expert 02 | B6: SKU-4001 | C6: MOCK-913351 | D6: Apple Watch SE | E6: 1 | F6: 0 | G6: 0 | H6: 0 | I6: 0 | J6: 0 | K6: 1 | L6: 0 | M6: Y | P6: =Setup!$A$6 -> Expert 03 | Q6: =SUMIF($A$4:$A$43,$P6,E$4:E$43) -> 1 | R6: =SUMIF($A$4:$A$43,$P6,F$4:F$43) -> 0 | S6: =SUMIF($A$4:$A$43,$P6,G$4:G$43) -> 0 | T6: =SUMIF($A$4:$A$43,$P6,H$4:H$43) -> 0 | U6: =SUMIF($A$4:$A$43,$P6,I$4:I$43) -> 0 | V6: =SUMIF($A$4:$A$43,$P6,J$4:J$43) -> 16 | W6: =SUMIF($A$4:$A$43,$P6,K$4:K$43) -> 2 | X6: =SUMIF($A$4:$A$43,$P6,L$4:L$43) -> 265.54
A7: Expert 03 | B7: SKU-1690 | C7: MOCK-540725 | D7: Accessory Only | E7: 0 | F7: 0 | G7: 0 | H7: 0 | I7: 0 | J7: 0 | K7: 0 | L7: 94.02 | M7: Y | P7: =Setup!$A$7 -> Expert 04 | Q7: =SUMIF($A$4:$A$43,$P7,E$4:E$43) -> 2 | R7: =SUMIF($A$4:$A$43,$P7,F$4:F$43) -> 0 | S7: =SUMIF($A$4:$A$43,$P7,G$4:G$43) -> 1 | T7: =SUMIF($A$4:$A$43,$P7,H$4:H$43) -> 0 | U7: =SUMIF($A$4:$A$43,$P7,I$4:I$43) -> 1 | V7: =SUMIF($A$4:$A$43,$P7,J$4:J$43) -> 16 | W7: =SUMIF($A$4:$A$43,$P7,K$4:K$43) -> 2 | X7: =SUMIF($A$4:$A$43,$P7,L$4:L$43) -> 213.21
A8: Expert 11 | B8: SKU-4737 | C8: MOCK-909584 | D8: iPhone 17 Pro Max | E8: 1 | F8: 0 | G8: 0 | H8: 0 | I8: 0 | J8: 0 | K8: 1 | L8: 104.76 | M8: Y | P8: =Setup!$A$8 -> Expert 05 | Q8: =SUMIF($A$4:$A$43,$P8,E$4:E$43) -> 0 | R8: =SUMIF($A$4:$A$43,$P8,F$4:F$43) -> 0 | S8: =SUMIF($A$4:$A$43,$P8,G$4:G$43) -> 0 | T8: =SUMIF($A$4:$A$43,$P8,H$4:H$43) -> 0 | U8: =SUMIF($A$4:$A$43,$P8,I$4:I$43) -> 0 | V8: =SUMIF($A$4:$A$43,$P8,J$4:J$43) -> 0 | W8: =SUMIF($A$4:$A$43,$P8,K$4:K$43) -> 0 | X8: =SUMIF($A$4:$A$43,$P8,L$4:L$43) -> 0
A9: Expert 02 | B9: SKU-5582 | C9: MOCK-292542 | D9: BYOD | E9: 0 | F9: 1 | G9: 0 | H9: 0 | I9: 0 | J9: 0 | K9: 0 | L9: 52.34 | M9: Y | P9: =Setup!$A$9 -> Expert 06 | Q9: =SUMIF($A$4:$A$43,$P9,E$4:E$43) -> 1 | R9: =SUMIF($A$4:$A$43,$P9,F$4:F$43) -> 1 | S9: =SUMIF($A$4:$A$43,$P9,G$4:G$43) -> 0 | T9: =SUMIF($A$4:$A$43,$P9,H$4:H$43) -> 0 | U9: =SUMIF($A$4:$A$43,$P9,I$4:I$43) -> 0 | V9: =SUMIF($A$4:$A$43,$P9,J$4:J$43) -> 16 | W9: =SUMIF($A$4:$A$43,$P9,K$4:K$43) -> 4 | X9: =SUMIF($A$4:$A$43,$P9,L$4:L$43) -> 305.59
A10: Expert 06 | B10: SKU-1939 | C10: MOCK-340025 | D10: Apple Watch Series 11 | E10: 0 | F10: 0 | G10: 0 | H10: 0 | I10: 0 | J10: 16 | K10: 1 | L10: 0 | M10: Y | P10: =Setup!$A$10 -> Expert 07 | Q10: =SUMIF($A$4:$A$43,$P10,E$4:E$43) -> 0 | R10: =SUMIF($A$4:$A$43,$P10,F$4:F$43) -> 0 | S10: =SUMIF($A$4:$A$43,$P10,G$4:G$43) -> 0 | T10: =SUMIF($A$4:$A$43,$P10,H$4:H$43) -> 0 | U10: =SUMIF($A$4:$A$43,$P10,I$4:I$43) -> 1 | V10: =SUMIF($A$4:$A$43,$P10,J$4:J$43) -> 0 | W10: =SUMIF($A$4:$A$43,$P10,K$4:K$43) -> 0 | X10: =SUMIF($A$4:$A$43,$P10,L$4:L$43) -> 64.36
A11: Expert 03 | B11: SKU-9459 | C11: MOCK-319280 | D11: Galaxy S26+ | E11: 1 | F11: 0 | G11: 0 | H11: 0 | I11: 0 | J11: 16 | K11: 1 | L11: 95.8 | M11: Y | P11: =Setup!$A$11 -> Expert 08 | Q11: =SUMIF($A$4:$A$43,$P11,E$4:E$43) -> 0 | R11: =SUMIF($A$4:$A$43,$P11,F$4:F$43) -> 0 | S11: =SUMIF($A$4:$A$43,$P11,G$4:G$43) -> 0 | T11: =SUMIF($A$4:$A$43,$P11,H$4:H$43) -> 0 | U11: =SUMIF($A$4:$A$43,$P11,I$4:I$43) -> 1 | V11: =SUMIF($A$4:$A$43,$P11,J$4:J$43) -> 24 | W11: =SUMIF($A$4:$A$43,$P11,K$4:K$43) -> 0 | X11: =SUMIF($A$4:$A$43,$P11,L$4:L$43) -> 61.22
A12: Expert 10 | B12: SKU-7698 | C12: MOCK-680674 | D12: Pixel 10 | E12: 0 | F12: 1 | G12: 0 | H12: 0 | I12: 0 | J12: 15 | K12: 1 | L12: 19.59 | M12: Y | P12: =Setup!$A$12 -> Expert 09 | Q12: =SUMIF($A$4:$A$43,$P12,E$4:E$43) -> 2 | R12: =SUMIF($A$4:$A$43,$P12,F$4:F$43) -> 1 | S12: =SUMIF($A$4:$A$43,$P12,G$4:G$43) -> 0 | T12: =SUMIF($A$4:$A$43,$P12,H$4:H$43) -> 0 | U12: =SUMIF($A$4:$A$43,$P12,I$4:I$43) -> 0 | V12: =SUMIF($A$4:$A$43,$P12,J$4:J$43) -> 57 | W12: =SUMIF($A$4:$A$43,$P12,K$4:K$43) -> 4 | X12: =SUMIF($A$4:$A$43,$P12,L$4:L$43) -> 149.47
A13: Expert 12 | B13: SKU-4941 | C13: MOCK-721874 | D13: iPhone 17 | E13: 1 | F13: 0 | G13: 0 | H13: 0 | I13: 0 | J13: 15 | K13: 1 | L13: 22.2 | M13: Y | P13: =Setup!$A$13 -> Expert 10 | Q13: =SUMIF($A$4:$A$43,$P13,E$4:E$43) -> 2 | R13: =SUMIF($A$4:$A$43,$P13,F$4:F$43) -> 1 | S13: =SUMIF($A$4:$A$43,$P13,G$4:G$43) -> 0 | T13: =SUMIF($A$4:$A$43,$P13,H$4:H$43) -> 0 | U13: =SUMIF($A$4:$A$43,$P13,I$4:I$43) -> 0 | V13: =SUMIF($A$4:$A$43,$P13,J$4:J$43) -> 30 | W13: =SUMIF($A$4:$A$43,$P13,K$4:K$43) -> 3 | X13: =SUMIF($A$4:$A$43,$P13,L$4:L$43) -> 19.59
A14: Expert 01 | B14: SKU-6477 | C14: MOCK-147008 | D14: Apple Watch SE | E14: 1 | F14: 0 | G14: 0 | H14: 0 | I14: 0 | J14: 0 | K14: 1 | L14: 8.62 | M14: Y | P14: =Setup!$A$14 -> Expert 11 | Q14: =SUMIF($A$4:$A$43,$P14,E$4:E$43) -> 3 | R14: =SUMIF($A$4:$A$43,$P14,F$4:F$43) -> 0 | S14: =SUMIF($A$4:$A$43,$P14,G$4:G$43) -> 0 | T14: =SUMIF($A$4:$A$43,$P14,H$4:H$43) -> 0 | U14: =SUMIF($A$4:$A$43,$P14,I$4:I$43) -> 0 | V14: =SUMIF($A$4:$A$43,$P14,J$4:J$43) -> 0 | W14: =SUMIF($A$4:$A$43,$P14,K$4:K$43) -> 3 | X14: =SUMIF($A$4:$A$43,$P14,L$4:L$43) -> 262.43
A15: Expert 11 | B15: SKU-4763 | C15: MOCK-495313 | D15: Pixel 10 Pro | E15: 1 | F15: 0 | G15: 0 | H15: 0 | I15: 0 | J15: 0 | K15: 1 | L15: 82.86 | M15: Y | P15: =Setup!$A$15 -> Expert 12 | Q15: =SUMIF($A$4:$A$43,$P15,E$4:E$43) -> 2 | R15: =SUMIF($A$4:$A$43,$P15,F$4:F$43) -> 1 | S15: =SUMIF($A$4:$A$43,$P15,G$4:G$43) -> 0 | T15: =SUMIF($A$4:$A$43,$P15,H$4:H$43) -> 0 | U15: =SUMIF($A$4:$A$43,$P15,I$4:I$43) -> 1 | V15: =SUMIF($A$4:$A$43,$P15,J$4:J$43) -> 63 | W15: =SUMIF($A$4:$A$43,$P15,K$4:K$43) -> 3 | X15: =SUMIF($A$4:$A$43,$P15,L$4:L$43) -> 232.04
A16: Expert 09 | B16: SKU-8639 | C16: MOCK-688758 | D16: Pixel 10 Pro | E16: 1 | F16: 0 | G16: 0 | H16: 0 | I16: 0 | J16: 0 | K16: 1 | L16: 64.14 | M16: Y | P16: STORE TOTAL | Q16: =SUM(Q4:Q15) -> 17 | R16: =SUM(R4:R15) -> 6 | S16: =SUM(S4:S15) -> 1 | T16: =SUM(T4:T15) -> 0 | U16: =SUM(U4:U15) -> 5 | V16: =SUM(V4:V15) -> 273 | W16: =SUM(W4:W15) -> 25 | X16: =SUM(X4:X15) -> 1820.04
A17: Expert 03 | B17: SKU-9658 | C17: MOCK-654697 | D17: Pixel 10 | E17: 0 | F17: 0 | G17: 0 | H17: 0 | I17: 0 | J17: 0 | K17: 1 | L17: 75.72 | M17: Y
A18: Expert 06 | B18: SKU-5840 | C18: MOCK-845574 | D18: Galaxy A17 | E18: 0 | F18: 0 | G18: 0 | H18: 0 | I18: 0 | J18: 0 | K18: 1 | L18: 86.05 | M18: Y
A19: Expert 02 | B19: SKU-5814 | C19: MOCK-253978 | D19: SIM Only | E19: 1 | F19: 0 | G19: 0 | H19: 0 | I19: 0 | J19: 0 | K19: 0 | L19: 105.95 | M19: Y
A20: Expert 04 | B20: SKU-8515 | C20: MOCK-190537 | D20: Galaxy S26 Ultra | E20: 1 | F20: 0 | G20: 1 | H20: 0 | I20: 0 | J20: 0 | K20: 1 | L20: 169.19 | M20: Y
A21: Expert 02 | B21: SKU-5844 | C21: MOCK-441927 | D21: iPhone 17 Pro | E21: 0 | F21: 1 | G21: 0 | H21: 0 | I21: 0 | J21: 18 | K21: 1 | L21: 0 | M21: Y
A22: Expert 10 | B22: SKU-3274 | C22: MOCK-189141 | D22: Pixel 10a | E22: 1 | F22: 0 | G22: 0 | H22: 0 | I22: 0 | J22: 0 | K22: 1 | L22: 0 | M22: Y
A23: Expert 10 | B23: SKU-6425 | C23: MOCK-230120 | D23: Apple Watch Ultra 3 | E23: 1 | F23: 0 | G23: 0 | H23: 0 | I23: 0 | J23: 15 | K23: 1 | L23: 0 | M23: Y
A24: Expert 12 | B24: SKU-1951 | C24: MOCK-642811 | D24: Galaxy Z Flip 7 | E24: 0 | F24: 1 | G24: 0 | H24: 0 | I24: 0 | J24: 33 | K24: 1 | L24: 173.12 | M24: Y
A25: Expert 07 | B25: SKU-7669 | C25: MOCK-288926 | D25: 5G Home Internet Gateway | E25: 0 | F25: 0 | G25: 0 | H25: 0 | I25: 1 | J25: 0 | K25: 0 | L25: 64.36 | M25: Y
A26: Expert 12 | B26: SKU-2963 | C26: MOCK-263588 | D26: Galaxy Tab A11 | E26: 1 | F26: 0 | G26: 0 | H26: 0 | I26: 0 | J26: 15 | K26: 1 | L26: 3.4 | M26: Y
A27: Expert 09 | B27: SKU-1457 | C27: MOCK-112471 | D27: moto g power | E27: 0 | F27: 0 | G27: 0 | H27: 0 | I27: 0 | J27: 24 | K27: 1 | L27: 0 | M27: Y
A28: Expert 12 | B28: SKU-1855 | C28: MOCK-178975 | D28: 5G Hotspot | E28: 0 | F28: 0 | G28: 0 | H28: 0 | I28: 1 | J28: 0 | K28: 0 | L28: 33.32 | M28: Y
... A36: Expert 04 | B36: SKU-8788 | C36: MOCK-195947 | D36: 5G Hotspot | E36: 0 | F36: 0 | G36: 0 | H36: 0 | I36: 1 | J36: 0 | K36: 0 | L36: 0 | M36: N

Sheet 4
A1: Day 4 — Daily Entry
A2: MOCK DATA — generated for portfolio use. No real employees, customers, device identifiers, or store numbers appear in this file.
A3: ME | B3: SKU (mock) | C3: IMEI / SIM (mock) | D3: Device | E3: Acts | F3: Pre | G3: TFB | H3: BTS | I3: Hint | J3: VAF $ | K3: Devices | L3: Acc $ | M3: Complete | P3: Mobile Expert | Q3: Acts | R3: Pre | S3: TFB | T3: BTS | U3: Hint | V3: VAF $ | W3: Devices | X3: Acc $
A4: Expert 03 | B4: SKU-7997 | C4: MOCK-542213 | D4: Accessory Only | E4: 0 | F4: 0 | G4: 0 | H4: 0 | I4: 0 | J4: 0 | K4: 0 | L4: 97.47 | M4: Y | P4: =Setup!$A$4 -> Expert 01 | Q4: =SUMIF($A$4:$A$43,$P4,E$4:E$43) -> 0 | R4: =SUMIF($A$4:$A$43,$P4,F$4:F$43) -> 0 | S4: =SUMIF($A$4:$A$43,$P4,G$4:G$43) -> 0 | T4: =SUMIF($A$4:$A$43,$P4,H$4:H$43) -> 0 | U4: =SUMIF($A$4:$A$43,$P4,I$4:I$43) -> 0 | V4: =SUMIF($A$4:$A$43,$P4,J$4:J$43) -> 15 | W4: =SUMIF($A$4:$A$43,$P4,K$4:K$43) -> 1 | X4: =SUMIF($A$4:$A$43,$P4,L$4:L$43) -> 0
A5: Expert 12 | B5: SKU-2843 | C5: MOCK-875939 | D5: Galaxy A37 | E5: 0 | F5: 1 | G5: 0 | H5: 0 | I5: 0 | J5: 0 | K5: 1 | L5: 0 | M5: Y | P5: =Setup!$A$5 -> Expert 02 | Q5: =SUMIF($A$4:$A$43,$P5,E$4:E$43) -> 0 | R5: =SUMIF($A$4:$A$43,$P5,F$4:F$43) -> 0 | S5: =SUMIF($A$4:$A$43,$P5,G$4:G$43) -> 0 | T5: =SUMIF($A$4:$A$43,$P5,H$4:H$43) -> 0 | U5: =SUMIF($A$4:$A$43,$P5,I$4:I$43) -> 1 | V5: =SUMIF($A$4:$A$43,$P5,J$4:J$43) -> 0 | W5: =SUMIF($A$4:$A$43,$P5,K$4:K$43) -> 0 | X5: =SUMIF($A$4:$A$43,$P5,L$4:L$43) -> 0
A6: Expert 07 | B6: SKU-2989 | C6: MOCK-767236 | D6: BYOD | E6: 0 | F6: 0 | G6: 0 | H6: 0 | I6: 0 | J6: 16 | K6: 0 | L6: 0 | M6: Y | P6: =Setup!$A$6 -> Expert 03 | Q6: =SUMIF($A$4:$A$43,$P6,E$4:E$43) -> 0 | R6: =SUMIF($A$4:$A$43,$P6,F$4:F$43) -> 1 | S6: =SUMIF($A$4:$A$43,$P6,G$4:G$43) -> 0 | T6: =SUMIF($A$4:$A$43,$P6,H$4:H$43) -> 0 | U6: =SUMIF($A$4:$A$43,$P6,I$4:I$43) -> 1 | V6: =SUMIF($A$4:$A$43,$P6,J$4:J$43) -> 18 | W6: =SUMIF($A$4:$A$43,$P6,K$4:K$43) -> 1 | X6: =SUMIF($A$4:$A$43,$P6,L$4:L$43) -> 309.26
A7: Expert 10 | B7: SKU-6223 | C7: MOCK-773163 | D7: 5G Home Internet Gateway | E7: 0 | F7: 0 | G7: 0 | H7: 0 | I7: 1 | J7: 33 | K7: 0 | L7: 163.98 | M7: Y | P7: =Setup!$A$7 -> Expert 04 | Q7: =SUMIF($A$4:$A$43,$P7,E$4:E$43) -> 0 | R7: =SUMIF($A$4:$A$43,$P7,F$4:F$43) -> 0 | S7: =SUMIF($A$4:$A$43,$P7,G$4:G$43) -> 0 | T7: =SUMIF($A$4:$A$43,$P7,H$4:H$43) -> 0 | U7: =SUMIF($A$4:$A$43,$P7,I$4:I$43) -> 0 | V7: =SUMIF($A$4:$A$43,$P7,J$4:J$43) -> 0 | W7: =SUMIF($A$4:$A$43,$P7,K$4:K$43) -> 1 | X7: =SUMIF($A$4:$A$43,$P7,L$4:L$43) -> 0
A8: Expert 10 | B8: SKU-5413 | C8: MOCK-724730 | D8: BYOD | E8: 0 | F8: 1 | G8: 0 | H8: 0 | I8: 0 | J8: 0 | K8: 0 | L8: 0 | M8: Y | P8: =Setup!$A$8 -> Expert 05 | Q8: =SUMIF($A$4:$A$43,$P8,E$4:E$43) -> 0 | R8: =SUMIF($A$4:$A$43,$P8,F$4:F$43) -> 0 | S8: =SUMIF($A$4:$A$43,$P8,G$4:G$43) -> 0 | T8: =SUMIF($A$4:$A$43,$P8,H$4:H$43) -> 0 | U8: =SUMIF($A$4:$A$43,$P8,I$4:I$43) -> 0 | V8: =SUMIF($A$4:$A$43,$P8,J$4:J$43) -> 0 | W8: =SUMIF($A$4:$A$43,$P8,K$4:K$43) -> 0 | X8: =SUMIF($A$4:$A$43,$P8,L$4:L$43) -> 0
A9: Expert 12 | B9: SKU-5223 | C9: MOCK-989714 | D9: SIM Only | E9: 1 | F9: 0 | G9: 0 | H9: 0 | I9: 0 | J9: 0 | K9: 0 | L9: 146.65 | M9: Y | P9: =Setup!$A$9 -> Expert 06 | Q9: =SUMIF($A$4:$A$43,$P9,E$4:E$43) -> 0 | R9: =SUMIF($A$4:$A$43,$P9,F$4:F$43) -> 0 | S9: =SUMIF($A$4:$A$43,$P9,G$4:G$43) -> 0 | T9: =SUMIF($A$4:$A$43,$P9,H$4:H$43) -> 0 | U9: =SUMIF($A$4:$A$43,$P9,I$4:I$43) -> 0 | V9: =SUMIF($A$4:$A$43,$P9,J$4:J$43) -> 0 | W9: =SUMIF($A$4:$A$43,$P9,K$4:K$43) -> 0 | X9: =SUMIF($A$4:$A$43,$P9,L$4:L$43) -> 0
A10: Expert 08 | B10: SKU-6431 | C10: MOCK-518283 | D10: iPad (11th Gen) | E10: 1 | F10: 0 | G10: 0 | H10: 0 | I10: 0 | J10: 24 | K10: 1 | L10: 37.23 | M10: Y | P10: =Setup!$A$10 -> Expert 07 | Q10: =SUMIF($A$4:$A$43,$P10,E$4:E$43) -> 0 | R10: =SUMIF($A$4:$A$43,$P10,F$4:F$43) -> 0 | S10: =SUMIF($A$4:$A$43,$P10,G$4:G$43) -> 0 | T10: =SUMIF($A$4:$A$43,$P10,H$4:H$43) -> 0 | U10: =SUMIF($A$4:$A$43,$P10,I$4:I$43) -> 0 | V10: =SUMIF($A$4:$A$43,$P10,J$4:J$43) -> 16 | W10: =SUMIF($A$4:$A$43,$P10,K$4:K$43) -> 0 | X10: =SUMIF($A$4:$A$43,$P10,L$4:L$43) -> 0
A11: Expert 03 | B11: SKU-1495 | C11: MOCK-454601 | D11: 5G Hotspot | E11: 0 | F11: 0 | G11: 0 | H11: 0 | I11: 1 | J11: 18 | K11: 0 | L11: 91.2 | M11: Y | P11: =Setup!$A$11 -> Expert 08 | Q11: =SUMIF($A$4:$A$43,$P11,E$4:E$43) -> 1 | R11: =SUMIF($A$4:$A$43,$P11,F$4:F$43) -> 0 | S11: =SUMIF($A$4:$A$43,$P11,G$4:G$43) -> 0 | T11: =SUMIF($A$4:$A$43,$P11,H$4:H$43) -> 0 | U11: =SUMIF($A$4:$A$43,$P11,I$4:I$43) -> 0 | V11: =SUMIF($A$4:$A$43,$P11,J$4:J$43) -> 64 | W11: =SUMIF($A$4:$A$43,$P11,K$4:K$43) -> 2 | X11: =SUMIF($A$4:$A$43,$P11,L$4:L$43) -> 84.34
A12: Expert 10 | B12: SKU-6977 | C12: MOCK-136053 | D12: moto g power | E12: 1 | F12: 0 | G12: 0 | H12: 0 | I12: 0 | J12: 16 | K12: 1 | L12: 0 | M12: Y | P12: =Setup!$A$12 -> Expert 09 | Q12: =SUMIF($A$4:$A$43,$P12,E$4:E$43) -> 0 | R12: =SUMIF($A$4:$A$43,$P12,F$4:F$43) -> 0 | S12: =SUMIF($A$4:$A$43,$P12,G$4:G$43) -> 0 | T12: =SUMIF($A$4:$A$43,$P12,H$4:H$43) -> 0 | U12: =SUMIF($A$4:$A$43,$P12,I$4:I$43) -> 0 | V12: =SUMIF($A$4:$A$43,$P12,J$4:J$43) -> 0 | W12: =SUMIF($A$4:$A$43,$P12,K$4:K$43) -> 0 | X12: =SUMIF($A$4:$A$43,$P12,L$4:L$43) -> 0
A13: Expert 01 | B13: SKU-2731 | C13: MOCK-550403 | D13: iPad (11th Gen) | E13: 0 | F13: 0 | G13: 0 | H13: 0 | I13: 0 | J13: 15 | K13: 1 | L13: 0 | M13: Y | P13: =Setup!$A$13 -> Expert 10 | Q13: =SUMIF($A$4:$A$43,$P13,E$4:E$43) -> 2 | R13: =SUMIF($A$4:$A$43,$P13,F$4:F$43) -> 1 | S13: =SUMIF($A$4:$A$43,$P13,G$4:G$43) -> 0 | T13: =SUMIF($A$4:$A$43,$P13,H$4:H$43) -> 1 | U13: =SUMIF($A$4:$A$43,$P13,I$4:I$43) -> 1 | V13: =SUMIF($A$4:$A$43,$P13,J$4:J$43) -> 88 | W13: =SUMIF($A$4:$A$43,$P13,K$4:K$43) -> 4 | X13: =SUMIF($A$4:$A$43,$P13,L$4:L$43) -> 186.9
A14: Expert 10 | B14: SKU-9577 | C14: MOCK-420304 | D14: Galaxy S26 Ultra | E14: 0 | F14: 0 | G14: 0 | H14: 0 | I14: 0 | J14: 15 | K14: 1 | L14: 0 | M14: N | P14: =Setup!$A$14 -> Expert 11 | Q14: =SUMIF($A$4:$A$43,$P14,E$4:E$43) -> 1 | R14: =SUMIF($A$4:$A$43,$P14,F$4:F$43) -> 0 | S14: =SUMIF($A$4:$A$43,$P14,G$4:G$43) -> 0 | T14: =SUMIF($A$4:$A$43,$P14,H$4:H$43) -> 0 | U14: =SUMIF($A$4:$A$43,$P14,I$4:I$43) -> 0 | V14: =SUMIF($A$4:$A$43,$P14,J$4:J$43) -> 0 | W14: =SUMIF($A$4:$A$43,$P14,K$4:K$43) -> 1 | X14: =SUMIF($A$4:$A$43,$P14,L$4:L$43) -> 0
A15: Expert 10 | B15: SKU-6465 | C15: MOCK-412828 | D15: Apple Watch Series 11 | E15: 1 | F15: 0 | G15: 0 | H15: 0 | I15: 0 | J15: 24 | K15: 1 | L15: 22.92 | M15: Y | P15: =Setup!$A$15 -> Expert 12 | Q15: =SUMIF($A$4:$A$43,$P15,E$4:E$43) -> 2 | R15: =SUMIF($A$4:$A$43,$P15,F$4:F$43) -> 2 | S15: =SUMIF($A$4:$A$43,$P15,G$4:G$43) -> 0 | T15: =SUMIF($A$4:$A$43,$P15,H$4:H$43) -> 0 | U15: =SUMIF($A$4:$A$43,$P15,I$4:I$43) -> 0 | V15: =SUMIF($A$4:$A$43,$P15,J$4:J$43) -> 24 | W15: =SUMIF($A$4:$A$43,$P15,K$4:K$43) -> 2 | X15: =SUMIF($A$4:$A$43,$P15,L$4:L$43) -> 236.23
A16: Expert 10 | B16: SKU-2269 | C16: MOCK-546434 | D16: Galaxy Watch 8 | E16: 0 | F16: 0 | G16: 0 | H16: 1 | I16: 0 | J16: 0 | K16: 1 | L16: 0 | M16: Y | P16: STORE TOTAL | Q16: =SUM(Q4:Q15) -> 6 | R16: =SUM(R4:R15) -> 4 | S16: =SUM(S4:S15) -> 0 | T16: =SUM(T4:T15) -> 1 | U16: =SUM(U4:U15) -> 3 | V16: =SUM(V4:V15) -> 225 | W16: =SUM(W4:W15) -> 12 | X16: =SUM(X4:X15) -> 816.73
A17: Expert 08 | B17: SKU-8197 | C17: MOCK-368140 | D17: Pixel 10 Pro | E17: 0 | F17: 0 | G17: 0 | H17: 0 | I17: 0 | J17: 24 | K17: 1 | L17: 47.11 | M17: Y
A18: Expert 08 | B18: SKU-4050 | C18: MOCK-805968 | D18: BYOD | E18: 0 | F18: 0 | G18: 0 | H18: 0 | I18: 0 | J18: 0 | K18: 0 | L18: 0 | M18: Y
A19: Expert 03 | B19: SKU-5003 | C19: MOCK-292005 | D19: Apple Watch Ultra 3 | E19: 0 | F19: 1 | G19: 0 | H19: 0 | I19: 0 | J19: 0 | K19: 1 | L19: 120.59 | M19: Y
A20: Expert 11 | B20: SKU-9139 | C20: MOCK-557336 | D20: iPhone 17 Air | E20: 1 | F20: 0 | G20: 0 | H20: 0 | I20: 0 | J20: 0 | K20: 1 | L20: 0 | M20: Y
A21: Expert 12 | B21: SKU-5178 | C21: MOCK-692118 | D21: Pixel 10 | E21: 1 | F21: 0 | G21: 0 | H21: 0 | I21: 0 | J21: 0 | K21: 1 | L21: 0 | M21: Y
A22: Expert 12 | B22: SKU-3402 | C22: MOCK-169926 | D22: Accessory Only | E22: 0 | F22: 1 | G22: 0 | H22: 0 | I22: 0 | J22: 24 | K22: 0 | L22: 89.58 | M22: Y
A23: Expert 08 | B23: SKU-1432 | C23: MOCK-920688 | D23: BYOD | E23: 0 | F23: 0 | G23: 0 | H23: 0 | I23: 0 | J23: 16 | K23: 0 | L23: 0 | M23: Y
A24: Expert 02 | B24: SKU-3322 | C24: MOCK-357866 | D24: 5G Hotspot | E24: 0 | F24: 0 | G24: 0 | H24: 0 | I24: 1 | J24: 0 | K24: 0 | L24: 0 | M24: Y
A25: Expert 04 | B25: SKU-4156 | C25: MOCK-871515 | D25: Galaxy Watch 8 | E25: 0 | F25: 0 | G25: 0 | H25: 0 | I25: 0 | J25: 0 | K25: 1 | L25: 0 | M25: Y

Sheet 5
A1: Day 5 — Daily Entry
A2: MOCK DATA — generated for portfolio use. No real employees, customers, device identifiers, or store numbers appear in this file.
A3: ME | B3: SKU (mock) | C3: IMEI / SIM (mock) | D3: Device | E3: Acts | F3: Pre | G3: TFB | H3: BTS | I3: Hint | J3: VAF $ | K3: Devices | L3: Acc $ | M3: Complete | P3: Mobile Expert | Q3: Acts | R3: Pre | S3: TFB | T3: BTS | U3: Hint | V3: VAF $ | W3: Devices | X3: Acc $
A4: Expert 07 | B4: SKU-5192 | C4: MOCK-825363 | D4: iPhone 17 | E4: 0 | F4: 0 | G4: 0 | H4: 0 | I4: 0 | J4: 0 | K4: 1 | L4: 148.8 | M4: Y | P4: =Setup!$A$4 -> Expert 01 | Q4: =SUMIF($A$4:$A$43,$P4,E$4:E$43) -> 2 | R4: =SUMIF($A$4:$A$43,$P4,F$4:F$43) -> 0 | S4: =SUMIF($A$4:$A$43,$P4,G$4:G$43) -> 0 | T4: =SUMIF($A$4:$A$43,$P4,H$4:H$43) -> 0 | U4: =SUMIF($A$4:$A$43,$P4,I$4:I$43) -> 0 | V4: =SUMIF($A$4:$A$43,$P4,J$4:J$43) -> 15 | W4: =SUMIF($A$4:$A$43,$P4,K$4:K$43) -> 2 | X4: =SUMIF($A$4:$A$43,$P4,L$4:L$43) -> 217.28
A5: Expert 02 | B5: SKU-6618 | C5: MOCK-419260 | D5: Pixel 10 Pro | E5: 1 | F5: 0 | G5: 0 | H5: 0 | I5: 0 | J5: 0 | K5: 1 | L5: 0 | M5: Y | P5: =Setup!$A$5 -> Expert 02 | Q5: =SUMIF($A$4:$A$43,$P5,E$4:E$43) -> 6 | R5: =SUMIF($A$4:$A$43,$P5,F$4:F$43) -> 0 | S5: =SUMIF($A$4:$A$43,$P5,G$4:G$43) -> 0 | T5: =SUMIF($A$4:$A$43,$P5,H$4:H$43) -> 0 | U5: =SUMIF($A$4:$A$43,$P5,I$4:I$43) -> 0 | V5: =SUMIF($A$4:$A$43,$P5,J$4:J$43) -> 0 | W5: =SUMIF($A$4:$A$43,$P5,K$4:K$43) -> 6 | X5: =SUMIF($A$4:$A$43,$P5,L$4:L$43) -> 285.13
A6: Expert 01 | B6: SKU-1470 | C6: MOCK-608404 | D6: Pixel 10a | E6: 1 | F6: 0 | G6: 0 | H6: 0 | I6: 0 | J6: 15 | K6: 1 | L6: 141.63 | M6: N | P6: =Setup!$A$6 -> Expert 03 | Q6: =SUMIF($A$4:$A$43,$P6,E$4:E$43) -> 1 | R6: =SUMIF($A$4:$A$43,$P6,F$4:F$43) -> 0 | S6: =SUMIF($A$4:$A$43,$P6,G$4:G$43) -> 0 | T6: =SUMIF($A$4:$A$43,$P6,H$4:H$43) -> 0 | U6: =SUMIF($A$4:$A$43,$P6,I$4:I$43) -> 0 | V6: =SUMIF($A$4:$A$43,$P6,J$4:J$43) -> 0 | W6: =SUMIF($A$4:$A$43,$P6,K$4:K$43) -> 1 | X6: =SUMIF($A$4:$A$43,$P6,L$4:L$43) -> 0
A7: Expert 08 | B7: SKU-5844 | C7: MOCK-287347 | D7: Pixel 10 | E7: 1 | F7: 0 | G7: 0 | H7: 0 | I7: 0 | J7: 33 | K7: 1 | L7: 36.85 | M7: Y | P7: =Setup!$A$7 -> Expert 04 | Q7: =SUMIF($A$4:$A$43,$P7,E$4:E$43) -> 3 | R7: =SUMIF($A$4:$A$43,$P7,F$4:F$43) -> 0 | S7: =SUMIF($A$4:$A$43,$P7,G$4:G$43) -> 0 | T7: =SUMIF($A$4:$A$43,$P7,H$4:H$43) -> 0 | U7: =SUMIF($A$4:$A$43,$P7,I$4:I$43) -> 0 | V7: =SUMIF($A$4:$A$43,$P7,J$4:J$43) -> 15 | W7: =SUMIF($A$4:$A$43,$P7,K$4:K$43) -> 3 | X7: =SUMIF($A$4:$A$43,$P7,L$4:L$43) -> 230.02
A8: Expert 04 | B8: SKU-3837 | C8: MOCK-763495 | D8: Pixel 10a | E8: 1 | F8: 0 | G8: 0 | H8: 0 | I8: 0 | J8: 0 | K8: 1 | L8: 0 | M8: Y | P8: =Setup!$A$8 -> Expert 05 | Q8: =SUMIF($A$4:$A$43,$P8,E$4:E$43) -> 2 | R8: =SUMIF($A$4:$A$43,$P8,F$4:F$43) -> 0 | S8: =SUMIF($A$4:$A$43,$P8,G$4:G$43) -> 0 | T8: =SUMIF($A$4:$A$43,$P8,H$4:H$43) -> 0 | U8: =SUMIF($A$4:$A$43,$P8,I$4:I$43) -> 0 | V8: =SUMIF($A$4:$A$43,$P8,J$4:J$43) -> 33 | W8: =SUMIF($A$4:$A$43,$P8,K$4:K$43) -> 2 | X8: =SUMIF($A$4:$A$43,$P8,L$4:L$43) -> 197.43
A9: Expert 04 | B9: SKU-6449 | C9: MOCK-668456 | D9: iPhone 17 Pro | E9: 1 | F9: 0 | G9: 0 | H9: 0 | I9: 0 | J9: 15 | K9: 1 | L9: 0 | M9: Y | P9: =Setup!$A$9 -> Expert 06 | Q9: =SUMIF($A$4:$A$43,$P9,E$4:E$43) -> 0 | R9: =SUMIF($A$4:$A$43,$P9,F$4:F$43) -> 0 | S9: =SUMIF($A$4:$A$43,$P9,G$4:G$43) -> 0 | T9: =SUMIF($A$4:$A$43,$P9,H$4:H$43) -> 0 | U9: =SUMIF($A$4:$A$43,$P9,I$4:I$43) -> 0 | V9: =SUMIF($A$4:$A$43,$P9,J$4:J$43) -> 0 | W9: =SUMIF($A$4:$A$43,$P9,K$4:K$43) -> 0 | X9: =SUMIF($A$4:$A$43,$P9,L$4:L$43) -> 0
A10: Expert 12 | B10: SKU-5922 | C10: MOCK-883713 | D10: Galaxy A17 | E10: 1 | F10: 0 | G10: 0 | H10: 0 | I10: 0 | J10: 0 | K10: 1 | L10: 179.67 | M10: Y | P10: =Setup!$A$10 -> Expert 07 | Q10: =SUMIF($A$4:$A$43,$P10,E$4:E$43) -> 3 | R10: =SUMIF($A$4:$A$43,$P10,F$4:F$43) -> 0 | S10: =SUMIF($A$4:$A$43,$P10,G$4:G$43) -> 0 | T10: =SUMIF($A$4:$A$43,$P10,H$4:H$43) -> 0 | U10: =SUMIF($A$4:$A$43,$P10,I$4:I$43) -> 0 | V10: =SUMIF($A$4:$A$43,$P10,J$4:J$43) -> 33 | W10: =SUMIF($A$4:$A$43,$P10,K$4:K$43) -> 4 | X10: =SUMIF($A$4:$A$43,$P10,L$4:L$43) -> 361.63
A11: Expert 10 | B11: SKU-8861 | C11: MOCK-256642 | D11: Pixel 10a | E11: 1 | F11: 0 | G11: 0 | H11: 0 | I11: 0 | J11: 18 | K11: 1 | L11: 0 | M11: Y | P11: =Setup!$A$11 -> Expert 08 | Q11: =SUMIF($A$4:$A$43,$P11,E$4:E$43) -> 2 | R11: =SUMIF($A$4:$A$43,$P11,F$4:F$43) -> 0 | S11: =SUMIF($A$4:$A$43,$P11,G$4:G$43) -> 0 | T11: =SUMIF($A$4:$A$43,$P11,H$4:H$43) -> 0 | U11: =SUMIF($A$4:$A$43,$P11,I$4:I$43) -> 0 | V11: =SUMIF($A$4:$A$43,$P11,J$4:J$43) -> 51 | W11: =SUMIF($A$4:$A$43,$P11,K$4:K$43) -> 3 | X11: =SUMIF($A$4:$A$43,$P11,L$4:L$43) -> 36.85
A12: Expert 02 | B12: SKU-3305 | C12: MOCK-545413 | D12: Galaxy Z Flip 7 | E12: 1 | F12: 0 | G12: 0 | H12: 0 | I12: 0 | J12: 0 | K12: 1 | L12: 15.5 | M12: Y | P12: =Setup!$A$12 -> Expert 09 | Q12: =SUMIF($A$4:$A$43,$P12,E$4:E$43) -> 0 | R12: =SUMIF($A$4:$A$43,$P12,F$4:F$43) -> 0 | S12: =SUMIF($A$4:$A$43,$P12,G$4:G$43) -> 0 | T12: =SUMIF($A$4:$A$43,$P12,H$4:H$43) -> 0 | U12: =SUMIF($A$4:$A$43,$P12,I$4:I$43) -> 0 | V12: =SUMIF($A$4:$A$43,$P12,J$4:J$43) -> 0 | W12: =SUMIF($A$4:$A$43,$P12,K$4:K$43) -> 0 | X12: =SUMIF($A$4:$A$43,$P12,L$4:L$43) -> 0
A13: Expert 02 | B13: SKU-6705 | C13: MOCK-228623 | D13: Apple Watch SE | E13: 1 | F13: 0 | G13: 0 | H13: 0 | I13: 0 | J13: 0 | K13: 1 | L13: 117.18 | M13: Y | P13: =Setup!$A$13 -> Expert 10 | Q13: =SUMIF($A$4:$A$43,$P13,E$4:E$43) -> 2 | R13: =SUMIF($A$4:$A$43,$P13,F$4:F$43) -> 0 | S13: =SUMIF($A$4:$A$43,$P13,G$4:G$43) -> 0 | T13: =SUMIF($A$4:$A$43,$P13,H$4:H$43) -> 0 | U13: =SUMIF($A$4:$A$43,$P13,I$4:I$43) -> 1 | V13: =SUMIF($A$4:$A$43,$P13,J$4:J$43) -> 67 | W13: =SUMIF($A$4:$A$43,$P13,K$4:K$43) -> 2 | X13: =SUMIF($A$4:$A$43,$P13,L$4:L$43) -> 196.9
